Workbook

Sheet Calculo1Vida
A1: DEMONSTRATIVO DE CÁLCULO
N3: Corr. monet. | O3: 45454
N4: Índice TJSP | O4: 100.83083
A6: Plano de saúde | C6: Cassi | F6: Categoria | M6: Tipo | N6: Coletivo por Adesão
A7: Mês aniv. cont. | C7: Novembro | F7: Vigência | G7: 43433
A9: OBJETO | C9: Reajuste por Sinistralidade
A11: Nome | C11: Gislane Kuke | H11: Data Nasc. | I11: 21985
A12: Ano | B12: Mês | C12: Valor pago | D12: Reaj. aplic. | E12: Idade | F12: Tipo reaj. | G12: Reaj. devido | H12: Valor devido | I12: Extra Pago | J12: Extra devido | K12: TOTAL PAGO | L12: TOTAL DEVIDO | M12: Diferença | N12: Índ corr monet | O12: Diferença corrigida
A13: 2004 | B13: 37987 | D13: 0 | E13: =IF(DAY(I$11)=0,"",IF(MONTH(I$11)<>MONTH($B13),"",YEAR($B13)-YEAR(I$11))) | G13: 0 | H13: =C13 -> 0 | K13: =C13+I13 -> 0 | L13: =H13+J13 -> 0 | N13: 31.052744
B14: 38018 | D14: =((C14/C13)-1) -> #DIV/0! | E14: =IF(DAY(I$11)=0,"",IF(MONTH(I$11)<>MONTH($B14),"",YEAR($B14)-YEAR(I$11))) | G14: 0 | H14: =H13*(1+G14) -> 0 | K14: =C14+I14 -> 0 | L14: =H14+J14 -> 0 | N14: 31.310481
B15: 38047 | D15: =((C15/C14)-1) -> #DIV/0! | E15: =IF(DAY(I$11)=0,"",IF(MONTH(I$11)<>MONTH($B15),"",YEAR($B15)-YEAR(I$11))) -> 44 | G15: 0 | H15: =H14*(1+G15) -> 0 | K15: =C15+I15 -> 0 | L15: =H15+J15 -> 0 | N15: 31.432591
B16: 38078 | D16: =((C16/C15)-1) -> #DIV/0! | E16: =IF(DAY(I$11)=0,"",IF(MONTH(I$11)<>MONTH($B16),"",YEAR($B16)-YEAR(I$11))) | G16: 0 | H16: =H15*(1+G16) -> 0 | K16: =C16+I16 -> 0 | L16: =H16+J16 -> 0 | N16: 31.611756
B17: 38108 | D17: =((C17/C16)-1) -> #DIV/0! | E17: =IF(DAY(I$11)=0,"",IF(MONTH(I$11)<>MONTH($B17),"",YEAR($B17)-YEAR(I$11))) | G17: 0 | H17: =H16*(1+G17) -> 0 | K17: =C17+I17 -> 0 | L17: =H17+J17 -> 0 | N17: 31.741364
B18: 38139 | D18: =((C18/C17)-1) -> #DIV/0! | E18: =IF(DAY(I$11)=0,"",IF(MONTH(I$11)<>MONTH($B18),"",YEAR($B18)-YEAR(I$11))) | G18: 0 | H18: =H17*(1+G18) -> 0 | K18: =C18+I18 -> 0 | L18: =H18+J18 -> 0 | N18: 31.868329
B19: 38169 | D19: =((C19/C18)-1) -> #DIV/0! | E19: =IF(DAY(I$11)=0,"",IF(MONTH(I$11)<>MONTH($B19),"",YEAR($B19)-YEAR(I$11))) | F19: Anual | G19: 0.11749877 | H19: =H18*(1+G19) -> 0 | K19: =C19+I19 -> 0 | L19: =H19+J19 -> 0 | N19: 32.02767
B20: 38200 | D20: =((C20/C19)-1) -> #DIV/0! | E20: =IF(DAY(I$11)=0,"",IF(MONTH(I$11)<>MONTH($B20),"",YEAR($B20)-YEAR(I$11))) | G20: 0 | H20: =H19*(1+G20) -> 0 | K20: =C20+I20 -> 0 | L20: =H20+J20 -> 0 | N20: 32.261471
B21: 38231 | D21: =((C21/C20)-1) -> #DIV/0! | E21: =IF(DAY(I$11)=0,"",IF(MONTH(I$11)<>MONTH($B21),"",YEAR($B21)-YEAR(I$11))) | G21: 0 | H21: =H20*(1+G21) -> 0 | K21: =C21+I21 -> 0 | L21: =H21+J21 -> 0 | N21: 32.422778
B22: 38261 | D22: =((C22/C21)-1) -> #DIV/0! | E22: =IF(DAY(I$11)=0,"",IF(MONTH(I$11)<>MONTH($B22),"",YEAR($B22)-YEAR(I$11))) | G22: 0 | H22: =H21*(1+G22) -> 0 | K22: =C22+I22 -> 0 | L22: =H22+J22 -> 0 | N22: 32.477896
B23: 38292 | D23: =((C23/C22)-1) -> #DIV/0! | E23: =IF(DAY(I$11)=0,"",IF(MONTH(I$11)<>MONTH($B23),"",YEAR($B23)-YEAR(I$11))) | G23: 0 | H23: =H22*(1+G23) -> 0 | K23: =C23+I23 -> 0 | L23: =H23+J23 -> 0 | N23: 32.533108
B24: 38322 | D24: =((C24/C23)-1) -> #DIV/0! | E24: =IF(DAY(I$11)=0,"",IF(MONTH(I$11)<>MONTH($B24),"",YEAR($B24)-YEAR(I$11))) | G24: 0 | H24: =H23*(1+G24) -> 0 | K24: =C24+I24 -> 0 | L24: =H24+J24 -> 0 | N24: 32.676253
A25: 2005 | B25: 38353 | D25: =((C25/C24)-1) -> #DIV/0! | E25: =IF(DAY(I$11)=0,"",IF(MONTH(I$11)<>MONTH($B25),"",YEAR($B25)-YEAR(I$11))) | G25: 0 | H25: =H24*(1+G25) -> 0 | K25: =C25+I25 -> 0 | L25: =H25+J25 -> 0 | N25: 32.957268
B26: 38384 | D26: =((C26/C25)-1) -> #DIV/0! | E26: =IF(DAY(I$11)=0,"",IF(MONTH(I$11)<>MONTH($B26),"",YEAR($B26)-YEAR(I$11))) | G26: 0 | H26: =H25*(1+G26) -> 0 | K26: =C26+I26 -> 0 | L26: =H26+J26 -> 0 | N26: 33.145124
B27: 38412 | D27: =((C27/C26)-1) -> #DIV/0! | E27: =IF(DAY(I$11)=0,"",IF(MONTH(I$11)<>MONTH($B27),"",YEAR($B27)-YEAR(I$11))) -> 45 | G27: 0 | H27: =H26*(1+G27) -> 0 | K27: =C27+I27 -> 0 | L27: =H27+J27 -> 0 | N27: 33.290962
B28: 38443 | D28: =((C28/C27)-1) -> #DIV/0! | E28: =IF(DAY(I$11)=0,"",IF(MONTH(I$11)<>MONTH($B28),"",YEAR($B28)-YEAR(I$11))) | G28: 0 | H28: =H27*(1+G28) -> 0 | K28: =C28+I28 -> 0 | L28: =H28+J28 -> 0 | N28: 33.533986
B29: 38473 | D29: =((C29/C28)-1) -> #DIV/0! | E29: =IF(DAY(I$11)=0,"",IF(MONTH(I$11)<>MONTH($B29),"",YEAR($B29)-YEAR(I$11))) | G29: 0 | H29: =H28*(1+G29) -> 0 | K29: =C29+I29 -> 0 | L29: =H29+J29 -> 0 | N29: 33.839145
B30: 38504 | D30: =((C30/C29)-1) -> #DIV/0! | E30: =IF(DAY(I$11)=0,"",IF(MONTH(I$11)<>MONTH($B30),"",YEAR($B30)-YEAR(I$11))) | G30: 0 | H30: =H29*(1+G30) -> 0 | K30: =C30+I30 -> 0 | L30: =H30+J30 -> 0 | N30: 34.076019
B31: 38534 | D31: =((C31/C30)-1) -> #DIV/0! | E31: =IF(DAY(I$11)=0,"",IF(MONTH(I$11)<>MONTH($B31),"",YEAR($B31)-YEAR(I$11))) | F31: Anual | G31: 0.1169 | H31: =H30*(1+G31) -> 0 | K31: =C31+I31 -> 0 | L31: =H31+J31 -> 0 | N31: 34.038535
B32: 38565 | D32: =((C32/C31)-1) -> #DIV/0! | E32: =IF(DAY(I$11)=0,"",IF(MONTH(I$11)<>MONTH($B32),"",YEAR($B32)-YEAR(I$11))) | G32: 0 | H32: =H31*(1+G32) -> 0 | K32: =C32+I32 -> 0 | L32: =H32+J32 -> 0 | N32: 34.048746
B33: 38596 | D33: =((C33/C32)-1) -> #DIV/0! | E33: =IF(DAY(I$11)=0,"",IF(MONTH(I$11)<>MONTH($B33),"",YEAR($B33)-YEAR(I$11))) | G33: 0 | H33: =H32*(1+G33) -> 0 | K33: =C33+I33 -> 0 | L33: =H33+J33 -> 0 | N33: 34.048746
B34: 38626 | D34: =((C34/C33)-1) -> #DIV/0! | E34: =IF(DAY(I$11)=0,"",IF(MONTH(I$11)<>MONTH($B34),"",YEAR($B34)-YEAR(I$11))) | G34: 0 | H34: =H33*(1+G34) -> 0 | K34: =C34+I34 -> 0 | L34: =H34+J34 -> 0 | N34: 34.099819
B35: 38657 | D35: =((C35/C34)-1) -> #DIV/0! | E35: =IF(DAY(I$11)=0,"",IF(MONTH(I$11)<>MONTH($B35),"",YEAR($B35)-YEAR(I$11))) | G35: 0 | H35: =H34*(1+G35) -> 0 | K35: =C35+I35 -> 0 | L35: =H35+J35 -> 0 | N35: 34.297597
B36: 38687 | D36: =((C36/C35)-1) -> #DIV/0! | E36: =IF(DAY(I$11)=0,"",IF(MONTH(I$11)<>MONTH($B36),"",YEAR($B36)-YEAR(I$11))) | G36: 0 | H36: =H35*(1+G36) -> 0 | K36: =C36+I36 -> 0 | L36: =H36+J36 -> 0 | N36: 34.482804
A37: 2006 | B37: 38718 | D37: =((C37/C36)-1) -> #DIV/0! | E37: =IF(DAY(I$11)=0,"",IF(MONTH(I$11)<>MONTH($B37),"",YEAR($B37)-YEAR(I$11))) | G37: 0 | H37: =H36*(1+G37) -> 0 | K37: =C37+I37 -> 0 | L37: =H37+J37 -> 0 | N37: 34.620735
B38: 38749 | D38: =((C38/C37)-1) -> #DIV/0! | E38: =IF(DAY(I$11)=0,"",IF(MONTH(I$11)<>MONTH($B38),"",YEAR($B38)-YEAR(I$11))) | G38: 0 | H38: =H37*(1+G38) -> 0 | K38: =C38+I38 -> 0 | L38: =H38+J38 -> 0 | N38: 34.752293
B39: 38777 | D39: =((C39/C38)-1) -> #DIV/0! | E39: =IF(DAY(I$11)=0,"",IF(MONTH(I$11)<>MONTH($B39),"",YEAR($B39)-YEAR(I$11))) -> 46 | G39: 0 | H39: =H38*(1+G39) -> 0 | K39: =C39+I39 -> 0 | L39: =H39+J39 -> 0 | N39: 34.832223
B40: 38808 | D40: =((C40/C39)-1) -> #DIV/0! | E40: =IF(DAY(I$11)=0,"",IF(MONTH(I$11)<>MONTH($B40),"",YEAR($B40)-YEAR(I$11))) | G40: 0 | H40: =H39*(1+G40) -> 0 | K40: =C40+I40 -> 0 | L40: =H40+J40 -> 0 | N40: 34.92627
B41: 38838 | D41: =((C41/C40)-1) -> #DIV/0! | E41: =IF(DAY(I$11)=0,"",IF(MONTH(I$11)<>MONTH($B41),"",YEAR($B41)-YEAR(I$11))) | G41: 0 | H41: =H40*(1+G41) -> 0 | K41: =C41+I41 -> 0 | L41: =H41+J41 -> 0 | N41: 34.968181
B42: 38869 | D42: =((C42/C41)-1) -> #DIV/0! | E42: =IF(DAY(I$11)=0,"",IF(MONTH(I$11)<>MONTH($B42),"",YEAR($B42)-YEAR(I$11))) | G42: 0 | H42: =H41*(1+G42) -> 0 | K42: =C42+I42 -> 0 | L42: =H42+J42 -> 0 | N42: 35.013639
B43: 38899 | D43: =((C43/C42)-1) -> #DIV/0! | E43: =IF(DAY(I$11)=0,"",IF(MONTH(I$11)<>MONTH($B43),"",YEAR($B43)-YEAR(I$11))) | F43: Anual | G43: 0.0889 | H43: =H42*(1+G43) -> 0 | K43: =C43+I43 -> 0 | L43: =H43+J43 -> 0 | N43: 34.989129
B44: 38930 | D44: =((C44/C43)-1) -> #DIV/0! | E44: =IF(DAY(I$11)=0,"",IF(MONTH(I$11)<>MONTH($B44),"",YEAR($B44)-YEAR(I$11))) | G44: 0 | H44: =H43*(1+G44) -> 0 | K44: =C44+I44 -> 0 | L44: =H44+J44 -> 0 | N44: 35.027617
...

Sheet Calculo2Vidas
A1: DEMONSTRATIVO DE CÁLCULO
M3: Corr. monet. | N3: 45454
M4: Índice TJSP | N4: 100.83083
D6: Plano de saúde | I6: Categoria | M6: Tipo
D7: Mês aniv. cont. | E7: =Relatorio!C5 -> 0 | I7: Vigência | J7: 38626
D9: OBJETO | E9: Reajuste por Sinistralidade
D11: Nome | I11: Data Nasc. | O11: Nome | T11: Data Nasc. | AB11: TOTAL | AJ11: TOTAL
A12: Ano | B12: Mês | D12: Valor pago | E12: Reaj. aplic. | F12: Idade | G12: Tipo reaj. | H12: Reaj. devido | I12: Vl. devido | J12: Extra Pago | K12: Extra devido | L12: TOTAL PAGO | M12: TOTAL DEVIDO | N12: Diferença | O12: Valor pago | P12: Reaj. aplic. | Q12: Idade | R12: Tipo reaj. | S12: Reaj. devido | T12: Vl. devido | U12: Extra Pago | V12: Extra devido | W12: TOTAL PAGO | X12: TOTAL DEVIDO | Y12: Diferença | Z12: Ano | AA12: Mês | AB12: Vl. tot. pago | AC12: Reaj. aplic. | AD12: Vl. tot. devido | AE12: Reaj. aplic. | AF12: Diferença | AG12: Índ corr monet | AH12: Diferença corrigida | AJ12: Vl. tot. pago | AK12: Reaj. aplic.
A13: 2004 | B13: 37987 | E13: 0 | H13: 0 | I13: =D13 -> 0 | L13: =D13+J13 -> 0 | M13: =I13+K13 -> 0 | P13: 0 | S13: 0 | T13: =O13 -> 0 | W13: =O13+U13 -> 0 | X13: =T13+V13 -> 0 | Z13: 2004 | AA13: 37987 | AB13: =L13+W13 -> 0 | AC13: 0 | AD13: =M13+X13 -> 0 | AE13: 0 | AG13: 31.052744 | AK13: 0
B14: 38018 | E14: =((D14/D13)-1) -> #DIV/0! | F14: =IF(DAY(J$11)=0,"",IF(MONTH(J$11)<>MONTH($B14),"",YEAR($B14)-YEAR(J$11))) | H14: 0 | I14: =I13*(1+H14) -> 0 | L14: =D14+J14 -> 0 | M14: =I14+K14 -> 0 | P14: =((O14/O13)-1) -> #DIV/0! | Q14: =IF(DAY(U$11)=0,"",IF(MONTH(U$11)<>MONTH($B14),"",YEAR($B14)-YEAR(U$11))) | S14: 0 | T14: =T13*(1+S14) -> 0 | W14: =O14+U14 -> 0 | X14: =T14+V14 -> 0 | AA14: 38018 | AB14: =L14+W14 -> 0 | AC14: =((AB14/AB13)-1) -> #DIV/0! | AD14: =M14+X14 -> 0 | AE14: =((AD14/AD13)-1) -> #DIV/0! | AG14: 31.310481 | AK14: =((AJ14/AJ13)-1) -> #DIV/0!
B15: 38047 | E15: =((D15/D14)-1) -> #DIV/0! | F15: =IF(DAY(J$11)=0,"",IF(MONTH(J$11)<>MONTH($B15),"",YEAR($B15)-YEAR(J$11))) | H15: 0 | I15: =I14*(1+H15) -> 0 | L15: =D15+J15 -> 0 | M15: =I15+K15 -> 0 | P15: =((O15/O14)-1) -> #DIV/0! | Q15: =IF(DAY(U$11)=0,"",IF(MONTH(U$11)<>MONTH($B15),"",YEAR($B15)-YEAR(U$11))) | S15: 0 | T15: =T14*(1+S15) -> 0 | W15: =O15+U15 -> 0 | X15: =T15+V15 -> 0 | AA15: 38047 | AB15: =L15+W15 -> 0 | AC15: =((AB15/AB14)-1) -> #DIV/0! | AD15: =M15+X15 -> 0 | AE15: =((AD15/AD14)-1) -> #DIV/0! | AG15: 31.432591 | AK15: =((AJ15/AJ14)-1) -> #DIV/0!
B16: 38078 | E16: =((D16/D15)-1) -> #DIV/0! | F16: =IF(DAY(J$11)=0,"",IF(MONTH(J$11)<>MONTH($B16),"",YEAR($B16)-YEAR(J$11))) | H16: 0 | I16: =I15*(1+H16) -> 0 | L16: =D16+J16 -> 0 | M16: =I16+K16 -> 0 | P16: =((O16/O15)-1) -> #DIV/0! | Q16: =IF(DAY(U$11)=0,"",IF(MONTH(U$11)<>MONTH($B16),"",YEAR($B16)-YEAR(U$11))) | S16: 0 | T16: =T15*(1+S16) -> 0 | W16: =O16+U16 -> 0 | X16: =T16+V16 -> 0 | AA16: 38078 | AB16: =L16+W16 -> 0 | AC16: =((AB16/AB15)-1) -> #DIV/0! | AD16: =M16+X16 -> 0 | AE16: =((AD16/AD15)-1) -> #DIV/0! | AG16: 31.611756 | AK16: =((AJ16/AJ15)-1) -> #DIV/0!
B17: 38108 | E17: =((D17/D16)-1) -> #DIV/0! | F17: =IF(DAY(J$11)=0,"",IF(MONTH(J$11)<>MONTH($B17),"",YEAR($B17)-YEAR(J$11))) | H17: 0 | I17: =I16*(1+H17) -> 0 | L17: =D17+J17 -> 0 | M17: =I17+K17 -> 0 | P17: =((O17/O16)-1) -> #DIV/0! | Q17: =IF(DAY(U$11)=0,"",IF(MONTH(U$11)<>MONTH($B17),"",YEAR($B17)-YEAR(U$11))) | S17: 0 | T17: =T16*(1+S17) -> 0 | W17: =O17+U17 -> 0 | X17: =T17+V17 -> 0 | AA17: 38108 | AB17: =L17+W17 -> 0 | AC17: =((AB17/AB16)-1) -> #DIV/0! | AD17: =M17+X17 -> 0 | AE17: =((AD17/AD16)-1) -> #DIV/0! | AG17: 31.741364 | AK17: =((AJ17/AJ16)-1) -> #DIV/0!
B18: 38139 | E18: =((D18/D17)-1) -> #DIV/0! | F18: =IF(DAY(J$11)=0,"",IF(MONTH(J$11)<>MONTH($B18),"",YEAR($B18)-YEAR(J$11))) | H18: 0 | I18: =I17*(1+H18) -> 0 | L18: =D18+J18 -> 0 | M18: =I18+K18 -> 0 | P18: =((O18/O17)-1) -> #DIV/0! | Q18: =IF(DAY(U$11)=0,"",IF(MONTH(U$11)<>MONTH($B18),"",YEAR($B18)-YEAR(U$11))) | S18: 0 | T18: =T17*(1+S18) -> 0 | W18: =O18+U18 -> 0 | X18: =T18+V18 -> 0 | AA18: 38139 | AB18: =L18+W18 -> 0 | AC18: =((AB18/AB17)-1) -> #DIV/0! | AD18: =M18+X18 -> 0 | AE18: =((AD18/AD17)-1) -> #DIV/0! | AG18: 31.868329 | AK18: =((AJ18/AJ17)-1) -> #DIV/0!
B19: 38169 | E19: =((D19/D18)-1) -> #DIV/0! | F19: =IF(DAY(J$11)=0,"",IF(MONTH(J$11)<>MONTH($B19),"",YEAR($B19)-YEAR(J$11))) | G19: Anual | H19: 0.11749877 | I19: =I18*(1+H19) -> 0 | L19: =D19+J19 -> 0 | M19: =I19+K19 -> 0 | P19: =((O19/O18)-1) -> #DIV/0! | Q19: =IF(DAY(U$11)=0,"",IF(MONTH(U$11)<>MONTH($B19),"",YEAR($B19)-YEAR(U$11))) | R19: Anual | S19: 0.11749877 | T19: =T18*(1+S19) -> 0 | W19: =O19+U19 -> 0 | X19: =T19+V19 -> 0 | AA19: 38169 | AB19: =L19+W19 -> 0 | AC19: =((AB19/AB18)-1) -> #DIV/0! | AD19: =M19+X19 -> 0 | AE19: =((AD19/AD18)-1) -> #DIV/0! | AG19: 32.02767 | AK19: =((AJ19/AJ18)-1) -> #DIV/0!
B20: 38200 | E20: =((D20/D19)-1) -> #DIV/0! | F20: =IF(DAY(J$11)=0,"",IF(MONTH(J$11)<>MONTH($B20),"",YEAR($B20)-YEAR(J$11))) | H20: 0 | I20: =I19*(1+H20) -> 0 | L20: =D20+J20 -> 0 | M20: =I20+K20 -> 0 | P20: =((O20/O19)-1) -> #DIV/0! | Q20: =IF(DAY(U$11)=0,"",IF(MONTH(U$11)<>MONTH($B20),"",YEAR($B20)-YEAR(U$11))) | S20: 0 | T20: =T19*(1+S20) -> 0 | W20: =O20+U20 -> 0 | X20: =T20+V20 -> 0 | AA20: 38200 | AB20: =L20+W20 -> 0 | AC20: =((AB20/AB19)-1) -> #DIV/0! | AD20: =M20+X20 -> 0 | AE20: =((AD20/AD19)-1) -> #DIV/0! | AG20: 32.261471 | AK20: =((AJ20/AJ19)-1) -> #DIV/0!
B21: 38231 | E21: =((D21/D20)-1) -> #DIV/0! | F21: =IF(DAY(J$11)=0,"",IF(MONTH(J$11)<>MONTH($B21),"",YEAR($B21)-YEAR(J$11))) | H21: 0 | I21: =I20*(1+H21) -> 0 | L21: =D21+J21 -> 0 | M21: =I21+K21 -> 0 | P21: =((O21/O20)-1) -> #DIV/0! | Q21: =IF(DAY(U$11)=0,"",IF(MONTH(U$11)<>MONTH($B21),"",YEAR($B21)-YEAR(U$11))) | S21: 0 | T21: =T20*(1+S21) -> 0 | W21: =O21+U21 -> 0 | X21: =T21+V21 -> 0 | AA21: 38231 | AB21: =L21+W21 -> 0 | AC21: =((AB21/AB20)-1) -> #DIV/0! | AD21: =M21+X21 -> 0 | AE21: =((AD21/AD20)-1) -> #DIV/0! | AG21: 32.422778 | AK21: =((AJ21/AJ20)-1) -> #DIV/0!
B22: 38261 | E22: =((D22/D21)-1) -> #DIV/0! | F22: =IF(DAY(J$11)=0,"",IF(MONTH(J$11)<>MONTH($B22),"",YEAR($B22)-YEAR(J$11))) | H22: 0 | I22: =I21*(1+H22) -> 0 | L22: =D22+J22 -> 0 | M22: =I22+K22 -> 0 | P22: =((O22/O21)-1) -> #DIV/0! | Q22: =IF(DAY(U$11)=0,"",IF(MONTH(U$11)<>MONTH($B22),"",YEAR($B22)-YEAR(U$11))) | S22: 0 | T22: =T21*(1+S22) -> 0 | W22: =O22+U22 -> 0 | X22: =T22+V22 -> 0 | AA22: 38261 | AB22: =L22+W22 -> 0 | AC22: =((AB22/AB21)-1) -> #DIV/0! | AD22: =M22+X22 -> 0 | AE22: =((AD22/AD21)-1) -> #DIV/0! | AG22: 32.477896 | AK22: =((AJ22/AJ21)-1) -> #DIV/0!
B23: 38292 | E23: =((D23/D22)-1) -> #DIV/0! | F23: =IF(DAY(J$11)=0,"",IF(MONTH(J$11)<>MONTH($B23),"",YEAR($B23)-YEAR(J$11))) | H23: 0 | I23: =I22*(1+H23) -> 0 | L23: =D23+J23 -> 0 | M23: =I23+K23 -> 0 | P23: =((O23/O22)-1) -> #DIV/0! | Q23: =IF(DAY(U$11)=0,"",IF(MONTH(U$11)<>MONTH($B23),"",YEAR($B23)-YEAR(U$11))) | S23: 0 | T23: =T22*(1+S23) -> 0 | W23: =O23+U23 -> 0 | X23: =T23+V23 -> 0 | AA23: 38292 | AB23: =L23+W23 -> 0 | AC23: =((AB23/AB22)-1) -> #DIV/0! | AD23: =M23+X23 -> 0 | AE23: =((AD23/AD22)-1) -> #DIV/0! | AG23: 32.533108 | AK23: =((AJ23/AJ22)-1) -> #DIV/0!
B24: 38322 | E24: =((D24/D23)-1) -> #DIV/0! | F24: =IF(DAY(J$11)=0,"",IF(MONTH(J$11)<>MONTH($B24),"",YEAR($B24)-YEAR(J$11))) | H24: 0 | I24: =I23*(1+H24) -> 0 | L24: =D24+J24 -> 0 | M24: =I24+K24 -> 0 | P24: =((O24/O23)-1) -> #DIV/0! | Q24: =IF(DAY(U$11)=0,"",IF(MONTH(U$11)<>MONTH($B24),"",YEAR($B24)-YEAR(U$11))) | S24: 0 | T24: =T23*(1+S24) -> 0 | W24: =O24+U24 -> 0 | X24: =T24+V24 -> 0 | AA24: 38322 | AB24: =L24+W24 -> 0 | AC24: =((AB24/AB23)-1) -> #DIV/0! | AD24: =M24+X24 -> 0 | AE24: =((AD24/AD23)-1) -> #DIV/0! | AG24: 32.676253 | AK24: =((AJ24/AJ23)-1) -> #DIV/0!
A25: 2005 | B25: 38353 | E25: =((D25/D24)-1) -> #DIV/0! | F25: =IF(DAY(J$11)=0,"",IF(MONTH(J$11)<>MONTH($B25),"",YEAR($B25)-YEAR(J$11))) | H25: 0 | I25: =I24*(1+H25) -> 0 | L25: =D25+J25 -> 0 | M25: =I25+K25 -> 0 | P25: =((O25/O24)-1) -> #DIV/0! | Q25: =IF(DAY(U$11)=0,"",IF(MONTH(U$11)<>MONTH($B25),"",YEAR($B25)-YEAR(U$11))) | S25: 0 | T25: =T24*(1+S25) -> 0 | W25: =O25+U25 -> 0 | X25: =T25+V25 -> 0 | Z25: 2005 | AA25: 38353 | AB25: =L25+W25 -> 0 | AC25: =((AB25/AB24)-1) -> #DIV/0! | AD25: =M25+X25 -> 0 | AE25: =((AD25/AD24)-1) -> #DIV/0! | AG25: 32.957268 | AK25: =((AJ25/AJ24)-1) -> #DIV/0!
B26: 38384 | E26: =((D26/D25)-1) -> #DIV/0! | F26: =IF(DAY(J$11)=0,"",IF(MONTH(J$11)<>MONTH($B26),"",YEAR($B26)-YEAR(J$11))) | H26: 0 | I26: =I25*(1+H26) -> 0 | L26: =D26+J26 -> 0 | M26: =I26+K26 -> 0 | P26: =((O26/O25)-1) -> #DIV/0! | Q26: =IF(DAY(U$11)=0,"",IF(MONTH(U$11)<>MONTH($B26),"",YEAR($B26)-YEAR(U$11))) | S26: 0 | T26: =T25*(1+S26) -> 0 | W26: =O26+U26 -> 0 | X26: =T26+V26 -> 0 | AA26: 38384 | AB26: =L26+W26 -> 0 | AC26: =((AB26/AB25)-1) -> #DIV/0! | AD26: =M26+X26 -> 0 | AE26: =((AD26/AD25)-1) -> #DIV/0! | AG26: 33.145124 | AK26: =((AJ26/AJ25)-1) -> #DIV/0!
B27: 38412 | E27: =((D27/D26)-1) -> #DIV/0! | F27: =IF(DAY(J$11)=0,"",IF(MONTH(J$11)<>MONTH($B27),"",YEAR($B27)-YEAR(J$11))) | H27: 0 | I27: =I26*(1+H27) -> 0 | L27: =D27+J27 -> 0 | M27: =I27+K27 -> 0 | P27: =((O27/O26)-1) -> #DIV/0! | Q27: =IF(DAY(U$11)=0,"",IF(MONTH(U$11)<>MONTH($B27),"",YEAR($B27)-YEAR(U$11))) | S27: 0 | T27: =T26*(1+S27) -> 0 | W27: =O27+U27 -> 0 | X27: =T27+V27 -> 0 | AA27: 38412 | AB27: =L27+W27 -> 0 | AC27: =((AB27/AB26)-1) -> #DIV/0! | AD27: =M27+X27 -> 0 | AE27: =((AD27/AD26)-1) -> #DIV/0! | AG27: 33.290962 | AK27: =((AJ27/AJ26)-1) -> #DIV/0!
B28: 38443 | E28: =((D28/D27)-1) -> #DIV/0! | F28: =IF(DAY(J$11)=0,"",IF(MONTH(J$11)<>MONTH($B28),"",YEAR($B28)-YEAR(J$11))) | H28: 0 | I28: =I27*(1+H28) -> 0 | L28: =D28+J28 -> 0 | M28: =I28+K28 -> 0 | P28: =((O28/O27)-1) -> #DIV/0! | Q28: =IF(DAY(U$11)=0,"",IF(MONTH(U$11)<>MONTH($B28),"",YEAR($B28)-YEAR(U$11))) | S28: 0 | T28: =T27*(1+S28) -> 0 | W28: =O28+U28 -> 0 | X28: =T28+V28 -> 0 | AA28: 38443 | AB28: =L28+W28 -> 0 | AC28: =((AB28/AB27)-1) -> #DIV/0! | AD28: =M28+X28 -> 0 | AE28: =((AD28/AD27)-1) -> #DIV/0! | AG28: 33.533986 | AK28: =((AJ28/AJ27)-1) -> #DIV/0!
B29: 38473 | E29: =((D29/D28)-1) -> #DIV/0! | F29: =IF(DAY(J$11)=0,"",IF(MONTH(J$11)<>MONTH($B29),"",YEAR($B29)-YEAR(J$11))) | H29: 0 | I29: =I28*(1+H29) -> 0 | L29: =D29+J29 -> 0 | M29: =I29+K29 -> 0 | P29: =((O29/O28)-1) -> #DIV/0! | Q29: =IF(DAY(U$11)=0,"",IF(MONTH(U$11)<>MONTH($B29),"",YEAR($B29)-YEAR(U$11))) | S29: 0 | T29: =T28*(1+S29) -> 0 | W29: =O29+U29 -> 0 | X29: =T29+V29 -> 0 | AA29: 38473 | AB29: =L29+W29 -> 0 | AC29: =((AB29/AB28)-1) -> #DIV/0! | AD29: =M29+X29 -> 0 | AE29: =((AD29/AD28)-1) -> #DIV/0! | AG29: 33.839145 | AK29: =((AJ29/AJ28)-1) -> #DIV/0!
B30: 38504 | E30: =((D30/D29)-1) -> #DIV/0! | F30: =IF(DAY(J$11)=0,"",IF(MONTH(J$11)<>MONTH($B30),"",YEAR($B30)-YEAR(J$11))) | H30: 0 | I30: =I29*(1+H30) -> 0 | L30: =D30+J30 -> 0 | M30: =I30+K30 -> 0 | P30: =((O30/O29)-1) -> #DIV/0! | Q30: =IF(DAY(U$11)=0,"",IF(MONTH(U$11)<>MONTH($B30),"",YEAR($B30)-YEAR(U$11))) | S30: 0 | T30: =T29*(1+S30) -> 0 | W30: =O30+U30 -> 0 | X30: =T30+V30 -> 0 | AA30: 38504 | AB30: =L30+W30 -> 0 | AC30: =((AB30/AB29)-1) -> #DIV/0! | AD30: =M30+X30 -> 0 | AE30: =((AD30/AD29)-1) -> #DIV/0! | AG30: 34.076019 | AK30: =((AJ30/AJ29)-1) -> #DIV/0!
B31: 38534 | E31: =((D31/D30)-1) -> #DIV/0! | F31: =IF(DAY(J$11)=0,"",IF(MONTH(J$11)<>MONTH($B31),"",YEAR($B31)-YEAR(J$11))) | G31: Anual | H31: 0.1169 | I31: =I30*(1+H31) -> 0 | L31: =D31+J31 -> 0 | M31: =I31+K31 -> 0 | P31: =((O31/O30)-1) -> #DIV/0! | Q31: =IF(DAY(U$11)=0,"",IF(MONTH(U$11)<>MONTH($B31),"",YEAR($B31)-YEAR(U$11))) | R31: Anual | S31: 0.1169 | T31: =T30*(1+S31) -> 0 | W31: =O31+U31 -> 0 | X31: =T31+V31 -> 0 | AA31: 38534 | AB31: =L31+W31 -> 0 | AC31: =((AB31/AB30)-1) -> #DIV/0! | AD31: =M31+X31 -> 0 | AE31: =((AD31/AD30)-1) -> #DIV/0! | AG31: 34.038535 | AK31: =((AJ31/AJ30)-1) -> #DIV/0!
B32: 38565 | E32: =((D32/D31)-1) -> #DIV/0! | F32: =IF(DAY(J$11)=0,"",IF(MONTH(J$11)<>MONTH($B32),"",YEAR($B32)-YEAR(J$11))) | H32: 0 | I32: =I31*(1+H32) -> 0 | L32: =D32+J32 -> 0 | M32: =I32+K32 -> 0 | P32: =((O32/O31)-1) -> #DIV/0! | Q32: =IF(DAY(U$11)=0,"",IF(MONTH(U$11)<>MONTH($B32),"",YEAR($B32)-YEAR(U$11))) | S32: 0 | T32: =T31*(1+S32) -> 0 | W32: =O32+U32 -> 0 | X32: =T32+V32 -> 0 | AA32: 38565 | AB32: =L32+W32 -> 0 | AC32: =((AB32/AB31)-1) -> #DIV/0! | AD32: =M32+X32 -> 0 | AE32: =((AD32/AD31)-1) -> #DIV/0! | AG32: 34.048746 | AK32: =((AJ32/AJ31)-1) -> #DIV/0!
B33: 38596 | E33: =((D33/D32)-1) -> #DIV/0! | F33: =IF(DAY(J$11)=0,"",IF(MONTH(J$11)<>MONTH($B33),"",YEAR($B33)-YEAR(J$11))) | H33: 0 | I33: =I32*(1+H33) -> 0 | L33: =D33+J33 -> 0 | M33: =I33+K33 -> 0 | P33: =((O33/O32)-1) -> #DIV/0! | Q33: =IF(DAY(U$11)=0,"",IF(MONTH(U$11)<>MONTH($B33),"",YEAR($B33)-YEAR(U$11))) | S33: 0 | T33: =T32*(1+S33) -> 0 | W33: =O33+U33 -> 0 | X33: =T33+V33 -> 0 | AA33: 38596 | AB33: =L33+W33 -> 0 | AC33: =((AB33/AB32)-1) -> #DIV/0! | AD33: =M33+X33 -> 0 | AE33: =((AD33/AD32)-1) -> #DIV/0! | AG33: 34.048746 | AK33: =((AJ33/AJ32)-1) -> #DIV/0!
B34: 38626 | E34: =((D34/D33)-1) -> #DIV/0! | F34: =IF(DAY(J$11)=0,"",IF(MONTH(J$11)<>MONTH($B34),"",YEAR($B34)-YEAR(J$11))) | H34: 0 | I34: =I33*(1+H34) -> 0 | L34: =D34+J34 -> 0 | M34: =I34+K34 -> 0 | P34: =((O34/O33)-1) -> #DIV/0! | Q34: =IF(DAY(U$11)=0,"",IF(MONTH(U$11)<>MONTH($B34),"",YEAR($B34)-YEAR(U$11))) | S34: 0 | T34: =T33*(1+S34) -> 0 | W34: =O34+U34 -> 0 | X34: =T34+V34 -> 0 | AA34: 38626 | AB34: =L34+W34 -> 0 | AC34: =((AB34/AB33)-1) -> #DIV/0! | AD34: =M34+X34 -> 0 | AE34: =((AD34/AD33)-1) -> #DIV/0! | AG34: 34.099819 | AK34: =((AJ34/AJ33)-1) -> #DIV/0!
B35: 38657 | E35: =((D35/D34)-1) -> #DIV/0! | F35: =IF(DAY(J$11)=0,"",IF(MONTH(J$11)<>MONTH($B35),"",YEAR($B35)-YEAR(J$11))) | H35: 0 | I35: =I34*(1+H35) -> 0 | L35: =D35+J35 -> 0 | M35: =I35+K35 -> 0 | P35: =((O35/O34)-1) -> #DIV/0! | Q35: =IF(DAY(U$11)=0,"",IF(MONTH(U$11)<>MONTH($B35),"",YEAR($B35)-YEAR(U$11))) | S35: 0 | T35: =T34*(1+S35) -> 0 | W35: =O35+U35 -> 0 | X35: =T35+V35 -> 0 | AA35: 38657 | AB35: =L35+W35 -> 0 | AC35: =((AB35/AB34)-1) -> #DIV/0! | AD35: =M35+X35 -> 0 | AE35: =((AD35/AD34)-1) -> #DIV/0! | AG35: 34.297597 | AK35: =((AJ35/AJ34)-1) -> #DIV/0!
B36: 38687 | E36: =((D36/D35)-1) -> #DIV/0! | F36: =IF(DAY(J$11)=0,"",IF(MONTH(J$11)<>MONTH($B36),"",YEAR($B36)-YEAR(J$11))) | H36: 0 | I36: =I35*(1+H36) -> 0 | L36: =D36+J36 -> 0 | M36: =I36+K36 -> 0 | P36: =((O36/O35)-1) -> #DIV/0! | Q36: =IF(DAY(U$11)=0,"",IF(MONTH(U$11)<>MONTH($B36),"",YEAR($B36)-YEAR(U$11))) | S36: 0 | T36: =T35*(1+S36) -> 0 | W36: =O36+U36 -> 0 | X36: =T36+V36 -> 0 | AA36: 38687 | AB36: =L36+W36 -> 0 | AC36: =((AB36/AB35)-1) -> #DIV/0! | AD36: =M36+X36 -> 0 | AE36: =((AD36/AD35)-1) -> #DIV/0! | AG36: 34.482804 | AK36: =((AJ36/AJ35)-1) -> #DIV/0!
A37: 2006 | B37: 38718 | E37: =((D37/D36)-1) -> #DIV/0! | F37: =IF(DAY(J$11)=0,"",IF(MONTH(J$11)<>MONTH($B37),"",YEAR($B37)-YEAR(J$11))) | H37: 0 | I37: =I36*(1+H37) -> 0 | L37: =D37+J37 -> 0 | M37: =I37+K37 -> 0 | P37: =((O37/O36)-1) -> #DIV/0! | Q37: =IF(DAY(U$11)=0,"",IF(MONTH(U$11)<>MONTH($B37),"",YEAR($B37)-YEAR(U$11))) | S37: 0 | T37: =T36*(1+S37) -> 0 | W37: =O37+U37 -> 0 | X37: =T37+V37 -> 0 | Z37: 2006 | AA37: 38718 | AB37: =L37+W37 -> 0 | AC37: =((AB37/AB36)-1) -> #DIV/0! | AD37: =M37+X37 -> 0 | AE37: =((AD37/AD36)-1) -> #DIV/0! | AG37: 34.620735 | AK37: =((AJ37/AJ36)-1) -> #DIV/0!
B38: 38749 | E38: =((D38/D37)-1) -> #DIV/0! | F38: =IF(DAY(J$11)=0,"",IF(MONTH(J$11)<>MONTH($B38),"",YEAR($B38)-YEAR(J$11))) | H38: 0 | I38: =I37*(1+H38) -> 0 | L38: =D38+J38 -> 0 | M38: =I38+K38 -> 0 | P38: =((O38/O37)-1) -> #DIV/0! | Q38: =IF(DAY(U$11)=0,"",IF(MONTH(U$11)<>MONTH($B38),"",YEAR($B38)-YEAR(U$11))) | S38: 0 | T38: =T37*(1+S38) -> 0 | W38: =O38+U38 -> 0 | X38: =T38+V38 -> 0 | AA38: 38749 | AB38: =L38+W38 -> 0 | AC38: =((AB38/AB37)-1) -> #DIV/0! | AD38: =M38+X38 -> 0 | AE38: =((AD38/AD37)-1) -> #DIV/0! | AG38: 34.752293 | AK38: =((AJ38/AJ37)-1) -> #DIV/0!
B39: 38777 | E39: =((D39/D38)-1) -> #DIV/0! | F39: =IF(DAY(J$11)=0,"",IF(MONTH(J$11)<>MONTH($B39),"",YEAR($B39)-YEAR(J$11))) | H39: 0 | I39: =I38*(1+H39) -> 0 | L39: =D39+J39 -> 0 | M39: =I39+K39 -> 0 | P39: =((O39/O38)-1) -> #DIV/0! | Q39: =IF(DAY(U$11)=0,"",IF(MONTH(U$11)<>MONTH($B39),"",YEAR($B39)-YEAR(U$11))) | S39: 0 | T39: =T38*(1+S39) -> 0 | W39: =O39+U39 -> 0 | X39: =T39+V39 -> 0 | AA39: 38777 | AB39: =L39+W39 -> 0 | AC39: =((AB39/AB38)-1) -> #DIV/0! | AD39: =M39+X39 -> 0 | AE39: =((AD39/AD38)-1) -> #DIV/0! | AG39: 34.832223 | AK39: =((AJ39/AJ38)-1) -> #DIV/0!
B40: 38808 | E40: =((D40/D39)-1) -> #DIV/0! | F40: =IF(DAY(J$11)=0,"",IF(MONTH(J$11)<>MONTH($B40),"",YEAR($B40)-YEAR(J$11))) | H40: 0 | I40: =I39*(1+H40) -> 0 | L40: =D40+J40 -> 0 | M40: =I40+K40 -> 0 | P40: =((O40/O39)-1) -> #DIV/0! | Q40: =IF(DAY(U$11)=0,"",IF(MONTH(U$11)<>MONTH($B40),"",YEAR($B40)-YEAR(U$11))) | S40: 0 | T40: =T39*(1+S40) -> 0 | W40: =O40+U40 -> 0 | X40: =T40+V40 -> 0 | AA40: 38808 | AB40: =L40+W40 -> 0 | AC40: =((AB40/AB39)-1) -> #DIV/0! | AD40: =M40+X40 -> 0 | AE40: =((AD40/AD39)-1) -> #DIV/0! | AG40: 34.92627 | AK40: =((AJ40/AJ39)-1) -> #DIV/0!
B41: 38838 | E41: =((D41/D40)-1) -> #DIV/0! | F41: =IF(DAY(J$11)=0,"",IF(MONTH(J$11)<>MONTH($B41),"",YEAR($B41)-YEAR(J$11))) | H41: 0 | I41: =I40*(1+H41) -> 0 | L41: =D41+J41 -> 0 | M41: =I41+K41 -> 0 | P41: =((O41/O40)-1) -> #DIV/0! | Q41: =IF(DAY(U$11)=0,"",IF(MONTH(U$11)<>MONTH($B41),"",YEAR($B41)-YEAR(U$11))) | S41: 0 | T41: =T40*(1+S41) -> 0 | W41: =O41+U41 -> 0 | X41: =T41+V41 -> 0 | AA41: 38838 | AB41: =L41+W41 -> 0 | AC41: =((AB41/AB40)-1) -> #DIV/0! | AD41: =M41+X41 -> 0 | AE41: =((AD41/AD40)-1) -> #DIV/0! | AG41: 34.968181 | AK41: =((AJ41/AJ40)-1) -> #DIV/0!
B42: 38869 | E42: =((D42/D41)-1) -> #DIV/0! | F42: =IF(DAY(J$11)=0,"",IF(MONTH(J$11)<>MONTH($B42),"",YEAR($B42)-YEAR(J$11))) | H42: 0 | I42: =I41*(1+H42) -> 0 | L42: =D42+J42 -> 0 | M42: =I42+K42 -> 0 | P42: =((O42/O41)-1) -> #DIV/0! | Q42: =IF(DAY(U$11)=0,"",IF(MONTH(U$11)<>MONTH($B42),"",YEAR($B42)-YEAR(U$11))) | S42: 0 | T42: =T41*(1+S42) -> 0 | W42: =O42+U42 -> 0 | X42: =T42+V42 -> 0 | AA42: 38869 | AB42: =L42+W42 -> 0 | AC42: =((AB42/AB41)-1) -> #DIV/0! | AD42: =M42+X42 -> 0 | AE42: =((AD42/AD41)-1) -> #DIV/0! | AG42: 35.013639 | AK42: =((AJ42/AJ41)-1) -> #DIV/0!
B43: 38899 | E43: =((D43/D42)-1) -> #DIV/0! | F43: =IF(DAY(J$11)=0,"",IF(MONTH(J$11)<>MONTH($B43),"",YEAR($B43)-YEAR(J$11))) | G43: Anual | H43: 0.0889 | I43: =I42*(1+H43) -> 0 | L43: =D43+J43 -> 0 | M43: =I43+K43 -> 0 | P43: =((O43/O42)-1) -> #DIV/0! | Q43: =IF(DAY(U$11)=0,"",IF(MONTH(U$11)<>MONTH($B43),"",YEAR($B43)-YEAR(U$11))) | R43: Anual | S43: 0.0889 | T43: =T42*(1+S43) -> 0 | W43: =O43+U43 -> 0 | X43: =T43+V43 -> 0 | AA43: 38899 | AB43: =L43+W43 -> 0 | AC43: =((AB43/AB42)-1) -> #DIV/0! | AD43: =M43+X43 -> 0 | AE43: =((AD43/AD42)-1) -> #DIV/0! | AG43: 34.989129 | AK43: =((AJ43/AJ42)-1) -> #DIV/0!
B44: 38930 | E44: =((D44/D43)-1) -> #DIV/0! | F44: =IF(DAY(J$11)=0,"",IF(MONTH(J$11)<>MONTH($B44),"",YEAR($B44)-YEAR(J$11))) | H44: 0 | I44: =I43*(1+H44) -> 0 | L44: =D44+J44 -> 0 | M44: =I44+K44 -> 0 | P44: =((O44/O43)-1) -> #DIV/0! | Q44: =IF(DAY(U$11)=0,"",IF(MONTH(U$11)<>MONTH($B44),"",YEAR($B44)-YEAR(U$11))) | S44: 0 | T44: =T43*(1+S44) -> 0 | W44: =O44+U44 -> 0 | X44: =T44+V44 -> 0 | AA44: 38930 | AB44: =L44+W44 -> 0 | AC44: =((AB44/AB43)-1) -> #DIV/0! | AD44: =M44+X44 -> 0 | AE44: =((AD44/AD43)-1) -> #DIV/0! | AG44: 35.027617 | AK44: =((AJ44/AJ43)-1) -> #DIV/0!
...

Sheet Calculo3Vidas
A1: DEMONSTRATIVO DE CÁLCULO
M3: Corr. monet. | N3: 45454
M4: Índice TJSP | N4: 100.83083
D6: Plano de saúde | I6: Categoria | J6: =Relatorio!E4 -> 0 | M6: Tipo
D7: Mês aniv. cont. | E7: =Relatorio!C5 -> 0 | I7: Vigência
D9: OBJETO | E9: Reajuste por Sinistralidade
D11: Nome | I11: Data Nasc. | O11: Nome | T11: Data Nasc. | Z11: Nome | AE11: Data Nasc. | AM11: TOTAL | AU11: TOTAL
A12: Ano | B12: Mês | D12: Valor pago | E12: Reaj. aplic. | F12: Idade | G12: Tipo reaj. | H12: Reaj. devido | I12: Vl. devido | J12: Extra Pago | K12: Extra devido | L12: TOTAL PAGO | M12: TOTAL DEVIDO | N12: Diferença | O12: Valor pago | P12: Reaj. aplic. | Q12: Idade | R12: Tipo reaj. | S12: Reaj. devido | T12: Vl. devido | U12: Extra Pago | V12: Extra devido | W12: TOTAL PAGO | X12: TOTAL DEVIDO | Y12: Diferença | Z12: Valor pago | AA12: Reaj. aplic. | AB12: Idade | AC12: Tipo reaj. | AD12: Reaj. devido | AE12: Vl. devido | AF12: Extra Pago | AG12: Extra devido | AH12: TOTAL PAGO | AI12: TOTAL DEVIDO | AJ12: Diferença | AK12: Ano | AL12: Mês | AM12: Vl. tot. pago | AN12: Reaj. aplic. | AO12: Vl. tot. devido | AP12: Reaj. aplic. | AQ12: Diferença | AR12: Índ corr monet | AS12: Diferença corrigida | AU12: Vl. tot. pago | AV12: Reaj. aplic.
A13: 2004 | B13: 37987 | E13: 0 | F13: =IF(DAY(J$11)=0,"",IF(MONTH(J$11)<>MONTH($B13),"",YEAR($B13)-YEAR(J$11))) | H13: 0 | I13: =D13 -> 0 | L13: =D13+J13 -> 0 | M13: =I13+K13 -> 0 | P13: 0 | Q13: =IF(DAY(U$11)=0,"",IF(MONTH(U$11)<>MONTH($B13),"",YEAR($B13)-YEAR(U$11))) | S13: 0 | T13: =O13 -> 0 | W13: =O13+U13 -> 0 | X13: =T13+V13 -> 0 | AA13: 0 | AB13: =IF(DAY(AF$11)=0,"",IF(MONTH(AF$11)<>MONTH($B13),"",YEAR($B13)-YEAR(AF$11))) | AD13: 0 | AE13: =Z13 -> 0 | AH13: =Z13+AF13 -> 0 | AI13: =AE13+AG13 -> 0 | AK13: 2004 | AL13: 37987 | AM13: =L13+W13+AH13 -> 0 | AN13: 0 | AO13: =M13+X13+AI13 -> 0 | AP13: 0 | AR13: 31.052744 | AV13: 0
B14: 38018 | E14: =((D14/D13)-1) -> #DIV/0! | F14: =IF(DAY(J$11)=0,"",IF(MONTH(J$11)<>MONTH($B14),"",YEAR($B14)-YEAR(J$11))) | H14: 0 | I14: =I13*(1+H14) -> 0 | L14: =D14+J14 -> 0 | M14: =I14+K14 -> 0 | P14: =((O14/O13)-1) -> #DIV/0! | Q14: =IF(DAY(U$11)=0,"",IF(MONTH(U$11)<>MONTH($B14),"",YEAR($B14)-YEAR(U$11))) | S14: 0 | T14: =T13*(1+S14) -> 0 | W14: =O14+U14 -> 0 | X14: =T14+V14 -> 0 | AA14: =((Z14/Z13)-1) -> #DIV/0! | AB14: =IF(DAY(AF$11)=0,"",IF(MONTH(AF$11)<>MONTH($B14),"",YEAR($B14)-YEAR(AF$11))) | AD14: 0 | AE14: =AE13*(1+AD14) -> 0 | AH14: =Z14+AF14 -> 0 | AI14: =AE14+AG14 -> 0 | AL14: 38018 | AM14: =L14+W14+AH14 -> 0 | AN14: =((AM14/AM13)-1) -> #DIV/0! | AO14: =M14+X14+AI14 -> 0 | AP14: =((AO14/AO13)-1) -> #DIV/0! | AR14: 31.310481 | AV14: =((AU14/AU13)-1) -> #DIV/0!
B15: 38047 | E15: =((D15/D14)-1) -> #DIV/0! | F15: =IF(DAY(J$11)=0,"",IF(MONTH(J$11)<>MONTH($B15),"",YEAR($B15)-YEAR(J$11))) | H15: 0 | I15: =I14*(1+H15) -> 0 | L15: =D15+J15 -> 0 | M15: =I15+K15 -> 0 | P15: =((O15/O14)-1) -> #DIV/0! | Q15: =IF(DAY(U$11)=0,"",IF(MONTH(U$11)<>MONTH($B15),"",YEAR($B15)-YEAR(U$11))) | S15: 0 | T15: =T14*(1+S15) -> 0 | W15: =O15+U15 -> 0 | X15: =T15+V15 -> 0 | AA15: =((Z15/Z14)-1) -> #DIV/0! | AB15: =IF(DAY(AF$11)=0,"",IF(MONTH(AF$11)<>MONTH($B15),"",YEAR($B15)-YEAR(AF$11))) | AD15: 0 | AE15: =AE14*(1+AD15) -> 0 | AH15: =Z15+AF15 -> 0 | AI15: =AE15+AG15 -> 0 | AL15: 38047 | AM15: =L15+W15+AH15 -> 0 | AN15: =((AM15/AM14)-1) -> #DIV/0! | AO15: =M15+X15+AI15 -> 0 | AP15: =((AO15/AO14)-1) -> #DIV/0! | AR15: 31.432591 | AV15: =((AU15/AU14)-1) -> #DIV/0!
B16: 38078 | E16: =((D16/D15)-1) -> #DIV/0! | F16: =IF(DAY(J$11)=0,"",IF(MONTH(J$11)<>MONTH($B16),"",YEAR($B16)-YEAR(J$11))) | H16: 0 | I16: =I15*(1+H16) -> 0 | L16: =D16+J16 -> 0 | M16: =I16+K16 -> 0 | P16: =((O16/O15)-1) -> #DIV/0! | Q16: =IF(DAY(U$11)=0,"",IF(MONTH(U$11)<>MONTH($B16),"",YEAR($B16)-YEAR(U$11))) | S16: 0 | T16: =T15*(1+S16) -> 0 | W16: =O16+U16 -> 0 | X16: =T16+V16 -> 0 | AA16: =((Z16/Z15)-1) -> #DIV/0! | AB16: =IF(DAY(AF$11)=0,"",IF(MONTH(AF$11)<>MONTH($B16),"",YEAR($B16)-YEAR(AF$11))) | AD16: 0 | AE16: =AE15*(1+AD16) -> 0 | AH16: =Z16+AF16 -> 0 | AI16: =AE16+AG16 -> 0 | AL16: 38078 | AM16: =L16+W16+AH16 -> 0 | AN16: =((AM16/AM15)-1) -> #DIV/0! | AO16: =M16+X16+AI16 -> 0 | AP16: =((AO16/AO15)-1) -> #DIV/0! | AR16: 31.611756 | AV16: =((AU16/AU15)-1) -> #DIV/0!
B17: 38108 | E17: =((D17/D16)-1) -> #DIV/0! | F17: =IF(DAY(J$11)=0,"",IF(MONTH(J$11)<>MONTH($B17),"",YEAR($B17)-YEAR(J$11))) | H17: 0 | I17: =I16*(1+H17) -> 0 | L17: =D17+J17 -> 0 | M17: =I17+K17 -> 0 | P17: =((O17/O16)-1) -> #DIV/0! | Q17: =IF(DAY(U$11)=0,"",IF(MONTH(U$11)<>MONTH($B17),"",YEAR($B17)-YEAR(U$11))) | S17: 0 | T17: =T16*(1+S17) -> 0 | W17: =O17+U17 -> 0 | X17: =T17+V17 -> 0 | AA17: =((Z17/Z16)-1) -> #DIV/0! | AB17: =IF(DAY(AF$11)=0,"",IF(MONTH(AF$11)<>MONTH($B17),"",YEAR($B17)-YEAR(AF$11))) | AD17: 0 | AE17: =AE16*(1+AD17) -> 0 | AH17: =Z17+AF17 -> 0 | AI17: =AE17+AG17 -> 0 | AL17: 38108 | AM17: =L17+W17+AH17 -> 0 | AN17: =((AM17/AM16)-1) -> #DIV/0! | AO17: =M17+X17+AI17 -> 0 | AP17: =((AO17/AO16)-1) -> #DIV/0! | AR17: 31.741364 | AV17: =((AU17/AU16)-1) -> #DIV/0!
B18: 38139 | E18: =((D18/D17)-1) -> #DIV/0! | F18: =IF(DAY(J$11)=0,"",IF(MONTH(J$11)<>MONTH($B18),"",YEAR($B18)-YEAR(J$11))) | H18: 0 | I18: =I17*(1+H18) -> 0 | L18: =D18+J18 -> 0 | M18: =I18+K18 -> 0 | P18: =((O18/O17)-1) -> #DIV/0! | Q18: =IF(DAY(U$11)=0,"",IF(MONTH(U$11)<>MONTH($B18),"",YEAR($B18)-YEAR(U$11))) | S18: 0 | T18: =T17*(1+S18) -> 0 | W18: =O18+U18 -> 0 | X18: =T18+V18 -> 0 | AA18: =((Z18/Z17)-1) -> #DIV/0! | AB18: =IF(DAY(AF$11)=0,"",IF(MONTH(AF$11)<>MONTH($B18),"",YEAR($B18)-YEAR(AF$11))) | AD18: 0 | AE18: =AE17*(1+AD18) -> 0 | AH18: =Z18+AF18 -> 0 | AI18: =AE18+AG18 -> 0 | AL18: 38139 | AM18: =L18+W18+AH18 -> 0 | AN18: =((AM18/AM17)-1) -> #DIV/0! | AO18: =M18+X18+AI18 -> 0 | AP18: =((AO18/AO17)-1) -> #DIV/0! | AR18: 31.868329 | AV18: =((AU18/AU17)-1) -> #DIV/0!
B19: 38169 | E19: =((D19/D18)-1) -> #DIV/0! | F19: =IF(DAY(J$11)=0,"",IF(MONTH(J$11)<>MONTH($B19),"",YEAR($B19)-YEAR(J$11))) | G19: Anual | H19: 0.11749877 | I19: =I18*(1+H19) -> 0 | L19: =D19+J19 -> 0 | M19: =I19+K19 -> 0 | P19: =((O19/O18)-1) -> #DIV/0! | Q19: =IF(DAY(U$11)=0,"",IF(MONTH(U$11)<>MONTH($B19),"",YEAR($B19)-YEAR(U$11))) | R19: Anual | S19: 0.11749877 | T19: =T18*(1+S19) -> 0 | W19: =O19+U19 -> 0 | X19: =T19+V19 -> 0 | AA19: =((Z19/Z18)-1) -> #DIV/0! | AB19: =IF(DAY(AF$11)=0,"",IF(MONTH(AF$11)<>MONTH($B19),"",YEAR($B19)-YEAR(AF$11))) | AC19: Anual | AD19: 0.11749877 | AE19: =AE18*(1+AD19) -> 0 | AH19: =Z19+AF19 -> 0 | AI19: =AE19+AG19 -> 0 | AL19: 38169 | AM19: =L19+W19+AH19 -> 0 | AN19: =((AM19/AM18)-1) -> #DIV/0! | AO19: =M19+X19+AI19 -> 0 | AP19: =((AO19/AO18)-1) -> #DIV/0! | AR19: 32.02767 | AV19: =((AU19/AU18)-1) -> #DIV/0!
B20: 38200 | E20: =((D20/D19)-1) -> #DIV/0! | F20: =IF(DAY(J$11)=0,"",IF(MONTH(J$11)<>MONTH($B20),"",YEAR($B20)-YEAR(J$11))) | H20: 0 | I20: =I19*(1+H20) -> 0 | L20: =D20+J20 -> 0 | M20: =I20+K20 -> 0 | P20: =((O20/O19)-1) -> #DIV/0! | Q20: =IF(DAY(U$11)=0,"",IF(MONTH(U$11)<>MONTH($B20),"",YEAR($B20)-YEAR(U$11))) | S20: 0 | T20: =T19*(1+S20) -> 0 | W20: =O20+U20 -> 0 | X20: =T20+V20 -> 0 | AA20: =((Z20/Z19)-1) -> #DIV/0! | AB20: =IF(DAY(AF$11)=0,"",IF(MONTH(AF$11)<>MONTH($B20),"",YEAR($B20)-YEAR(AF$11))) | AD20: 0 | AE20: =AE19*(1+AD20) -> 0 | AH20: =Z20+AF20 -> 0 | AI20: =AE20+AG20 -> 0 | AL20: 38200 | AM20: =L20+W20+AH20 -> 0 | AN20: =((AM20/AM19)-1) -> #DIV/0! | AO20: =M20+X20+AI20 -> 0 | AP20: =((AO20/AO19)-1) -> #DIV/0! | AR20: 32.261471 | AV20: =((AU20/AU19)-1) -> #DIV/0!
B21: 38231 | E21: =((D21/D20)-1) -> #DIV/0! | F21: =IF(DAY(J$11)=0,"",IF(MONTH(J$11)<>MONTH($B21),"",YEAR($B21)-YEAR(J$11))) | H21: 0 | I21: =I20*(1+H21) -> 0 | L21: =D21+J21 -> 0 | M21: =I21+K21 -> 0 | P21: =((O21/O20)-1) -> #DIV/0! | Q21: =IF(DAY(U$11)=0,"",IF(MONTH(U$11)<>MONTH($B21),"",YEAR($B21)-YEAR(U$11))) | S21: 0 | T21: =T20*(1+S21) -> 0 | W21: =O21+U21 -> 0 | X21: =T21+V21 -> 0 | AA21: =((Z21/Z20)-1) -> #DIV/0! | AB21: =IF(DAY(AF$11)=0,"",IF(MONTH(AF$11)<>MONTH($B21),"",YEAR($B21)-YEAR(AF$11))) | AD21: 0 | AE21: =AE20*(1+AD21) -> 0 | AH21: =Z21+AF21 -> 0 | AI21: =AE21+AG21 -> 0 | AL21: 38231 | AM21: =L21+W21+AH21 -> 0 | AN21: =((AM21/AM20)-1) -> #DIV/0! | AO21: =M21+X21+AI21 -> 0 | AP21: =((AO21/AO20)-1) -> #DIV/0! | AR21: 32.422778 | AV21: =((AU21/AU20)-1) -> #DIV/0!
B22: 38261 | E22: =((D22/D21)-1) -> #DIV/0! | F22: =IF(DAY(J$11)=0,"",IF(MONTH(J$11)<>MONTH($B22),"",YEAR($B22)-YEAR(J$11))) | H22: 0 | I22: =I21*(1+H22) -> 0 | L22: =D22+J22 -> 0 | M22: =I22+K22 -> 0 | P22: =((O22/O21)-1) -> #DIV/0! | Q22: =IF(DAY(U$11)=0,"",IF(MONTH(U$11)<>MONTH($B22),"",YEAR($B22)-YEAR(U$11))) | S22: 0 | T22: =T21*(1+S22) -> 0 | W22: =O22+U22 -> 0 | X22: =T22+V22 -> 0 | AA22: =((Z22/Z21)-1) -> #DIV/0! | AB22: =IF(DAY(AF$11)=0,"",IF(MONTH(AF$11)<>MONTH($B22),"",YEAR($B22)-YEAR(AF$11))) | AD22: 0 | AE22: =AE21*(1+AD22) -> 0 | AH22: =Z22+AF22 -> 0 | AI22: =AE22+AG22 -> 0 | AL22: 38261 | AM22: =L22+W22+AH22 -> 0 | AN22: =((AM22/AM21)-1) -> #DIV/0! | AO22: =M22+X22+AI22 -> 0 | AP22: =((AO22/AO21)-1) -> #DIV/0! | AR22: 32.477896 | AV22: =((AU22/AU21)-1) -> #DIV/0!
B23: 38292 | E23: =((D23/D22)-1) -> #DIV/0! | F23: =IF(DAY(J$11)=0,"",IF(MONTH(J$11)<>MONTH($B23),"",YEAR($B23)-YEAR(J$11))) | H23: 0 | I23: =I22*(1+H23) -> 0 | L23: =D23+J23 -> 0 | M23: =I23+K23 -> 0 | P23: =((O23/O22)-1) -> #DIV/0! | Q23: =IF(DAY(U$11)=0,"",IF(MONTH(U$11)<>MONTH($B23),"",YEAR($B23)-YEAR(U$11))) | S23: 0 | T23: =T22*(1+S23) -> 0 | W23: =O23+U23 -> 0 | X23: =T23+V23 -> 0 | AA23: =((Z23/Z22)-1) -> #DIV/0! | AB23: =IF(DAY(AF$11)=0,"",IF(MONTH(AF$11)<>MONTH($B23),"",YEAR($B23)-YEAR(AF$11))) | AD23: 0 | AE23: =AE22*(1+AD23) -> 0 | AH23: =Z23+AF23 -> 0 | AI23: =AE23+AG23 -> 0 | AL23: 38292 | AM23: =L23+W23+AH23 -> 0 | AN23: =((AM23/AM22)-1) -> #DIV/0! | AO23: =M23+X23+AI23 -> 0 | AP23: =((AO23/AO22)-1) -> #DIV/0! | AR23: 32.533108 | AV23: =((AU23/AU22)-1) -> #DIV/0!
B24: 38322 | E24: =((D24/D23)-1) -> #DIV/0! | F24: =IF(DAY(J$11)=0,"",IF(MONTH(J$11)<>MONTH($B24),"",YEAR($B24)-YEAR(J$11))) | H24: 0 | I24: =I23*(1+H24) -> 0 | L24: =D24+J24 -> 0 | M24: =I24+K24 -> 0 | P24: =((O24/O23)-1) -> #DIV/0! | Q24: =IF(DAY(U$11)=0,"",IF(MONTH(U$11)<>MONTH($B24),"",YEAR($B24)-YEAR(U$11))) | S24: 0 | T24: =T23*(1+S24) -> 0 | W24: =O24+U24 -> 0 | X24: =T24+V24 -> 0 | AA24: =((Z24/Z23)-1) -> #DIV/0! | AB24: =IF(DAY(AF$11)=0,"",IF(MONTH(AF$11)<>MONTH($B24),"",YEAR($B24)-YEAR(AF$11))) | AD24: 0 | AE24: =AE23*(1+AD24) -> 0 | AH24: =Z24+AF24 -> 0 | AI24: =AE24+AG24 -> 0 | AL24: 38322 | AM24: =L24+W24+AH24 -> 0 | AN24: =((AM24/AM23)-1) -> #DIV/0! | AO24: =M24+X24+AI24 -> 0 | AP24: =((AO24/AO23)-1) -> #DIV/0! | AR24: 32.676253 | AV24: =((AU24/AU23)-1) -> #DIV/0!
A25: 2005 | B25: 38353 | E25: =((D25/D24)-1) -> #DIV/0! | F25: =IF(DAY(J$11)=0,"",IF(MONTH(J$11)<>MONTH($B25),"",YEAR($B25)-YEAR(J$11))) | H25: 0 | I25: =I24*(1+H25) -> 0 | L25: =D25+J25 -> 0 | M25: =I25+K25 -> 0 | P25: =((O25/O24)-1) -> #DIV/0! | Q25: =IF(DAY(U$11)=0,"",IF(MONTH(U$11)<>MONTH($B25),"",YEAR($B25)-YEAR(U$11))) | S25: 0 | T25: =T24*(1+S25) -> 0 | W25: =O25+U25 -> 0 | X25: =T25+V25 -> 0 | AA25: =((Z25/Z24)-1) -> #DIV/0! | AB25: =IF(DAY(AF$11)=0,"",IF(MONTH(AF$11)<>MONTH($B25),"",YEAR($B25)-YEAR(AF$11))) | AD25: 0 | AE25: =AE24*(1+AD25) -> 0 | AH25: =Z25+AF25 -> 0 | AI25: =AE25+AG25 -> 0 | AK25: 2005 | AL25: 38353 | AM25: =L25+W25+AH25 -> 0 | AN25: =((AM25/AM24)-1) -> #DIV/0! | AO25: =M25+X25+AI25 -> 0 | AP25: =((AO25/AO24)-1) -> #DIV/0! | AR25: 32.957268 | AV25: =((AU25/AU24)-1) -> #DIV/0!
B26: 38384 | E26: =((D26/D25)-1) -> #DIV/0! | F26: =IF(DAY(J$11)=0,"",IF(MONTH(J$11)<>MONTH($B26),"",YEAR($B26)-YEAR(J$11))) | H26: 0 | I26: =I25*(1+H26) -> 0 | L26: =D26+J26 -> 0 | M26: =I26+K26 -> 0 | P26: =((O26/O25)-1) -> #DIV/0! | Q26: =IF(DAY(U$11)=0,"",IF(MONTH(U$11)<>MONTH($B26),"",YEAR($B26)-YEAR(U$11))) | S26: 0 | T26: =T25*(1+S26) -> 0 | W26: =O26+U26 -> 0 | X26: =T26+V26 -> 0 | AA26: =((Z26/Z25)-1) -> #DIV/0! | AB26: =IF(DAY(AF$11)=0,"",IF(MONTH(AF$11)<>MONTH($B26),"",YEAR($B26)-YEAR(AF$11))) | AD26: 0 | AE26: =AE25*(1+AD26) -> 0 | AH26: =Z26+AF26 -> 0 | AI26: =AE26+AG26 -> 0 | AL26: 38384 | AM26: =L26+W26+AH26 -> 0 | AN26: =((AM26/AM25)-1) -> #DIV/0! | AO26: =M26+X26+AI26 -> 0 | AP26: =((AO26/AO25)-1) -> #DIV/0! | AR26: 33.145124 | AV26: =((AU26/AU25)-1) -> #DIV/0!
B27: 38412 | E27: =((D27/D26)-1) -> #DIV/0! | F27: =IF(DAY(J$11)=0,"",IF(MONTH(J$11)<>MONTH($B27),"",YEAR($B27)-YEAR(J$11))) | H27: 0 | I27: =I26*(1+H27) -> 0 | L27: =D27+J27 -> 0 | M27: =I27+K27 -> 0 | P27: =((O27/O26)-1) -> #DIV/0! | Q27: =IF(DAY(U$11)=0,"",IF(MONTH(U$11)<>MONTH($B27),"",YEAR($B27)-YEAR(U$11))) | S27: 0 | T27: =T26*(1+S27) -> 0 | W27: =O27+U27 -> 0 | X27: =T27+V27 -> 0 | AA27: =((Z27/Z26)-1) -> #DIV/0! | AB27: =IF(DAY(AF$11)=0,"",IF(MONTH(AF$11)<>MONTH($B27),"",YEAR($B27)-YEAR(AF$11))) | AD27: 0 | AE27: =AE26*(1+AD27) -> 0 | AH27: =Z27+AF27 -> 0 | AI27: =AE27+AG27 -> 0 | AL27: 38412 | AM27: =L27+W27+AH27 -> 0 | AN27: =((AM27/AM26)-1) -> #DIV/0! | AO27: =M27+X27+AI27 -> 0 | AP27: =((AO27/AO26)-1) -> #DIV/0! | AR27: 33.290962 | AV27: =((AU27/AU26)-1) -> #DIV/0!
B28: 38443 | E28: =((D28/D27)-1) -> #DIV/0! | F28: =IF(DAY(J$11)=0,"",IF(MONTH(J$11)<>MONTH($B28),"",YEAR($B28)-YEAR(J$11))) | H28: 0 | I28: =I27*(1+H28) -> 0 | L28: =D28+J28 -> 0 | M28: =I28+K28 -> 0 | P28: =((O28/O27)-1) -> #DIV/0! | Q28: =IF(DAY(U$11)=0,"",IF(MONTH(U$11)<>MONTH($B28),"",YEAR($B28)-YEAR(U$11))) | S28: 0 | T28: =T27*(1+S28) -> 0 | W28: =O28+U28 -> 0 | X28: =T28+V28 -> 0 | AA28: =((Z28/Z27)-1) -> #DIV/0! | AB28: =IF(DAY(AF$11)=0,"",IF(MONTH(AF$11)<>MONTH($B28),"",YEAR($B28)-YEAR(AF$11))) | AD28: 0 | AE28: =AE27*(1+AD28) -> 0 | AH28: =Z28+AF28 -> 0 | AI28: =AE28+AG28 -> 0 | AL28: 38443 | AM28: =L28+W28+AH28 -> 0 | AN28: =((AM28/AM27)-1) -> #DIV/0! | AO28: =M28+X28+AI28 -> 0 | AP28: =((AO28/AO27)-1) -> #DIV/0! | AR28: 33.533986 | AV28: =((AU28/AU27)-1) -> #DIV/0!
B29: 38473 | E29: =((D29/D28)-1) -> #DIV/0! | F29: =IF(DAY(J$11)=0,"",IF(MONTH(J$11)<>MONTH($B29),"",YEAR($B29)-YEAR(J$11))) | H29: 0 | I29: =I28*(1+H29) -> 0 | L29: =D29+J29 -> 0 | M29: =I29+K29 -> 0 | P29: =((O29/O28)-1) -> #DIV/0! | Q29: =IF(DAY(U$11)=0,"",IF(MONTH(U$11)<>MONTH($B29),"",YEAR($B29)-YEAR(U$11))) | S29: 0 | T29: =T28*(1+S29) -> 0 | W29: =O29+U29 -> 0 | X29: =T29+V29 -> 0 | AA29: =((Z29/Z28)-1) -> #DIV/0! | AB29: =IF(DAY(AF$11)=0,"",IF(MONTH(AF$11)<>MONTH($B29),"",YEAR($B29)-YEAR(AF$11))) | AD29: 0 | AE29: =AE28*(1+AD29) -> 0 | AH29: =Z29+AF29 -> 0 | AI29: =AE29+AG29 -> 0 | AL29: 38473 | AM29: =L29+W29+AH29 -> 0 | AN29: =((AM29/AM28)-1) -> #DIV/0! | AO29: =M29+X29+AI29 -> 0 | AP29: =((AO29/AO28)-1) -> #DIV/0! | AR29: 33.839145 | AV29: =((AU29/AU28)-1) -> #DIV/0!
B30: 38504 | E30: =((D30/D29)-1) -> #DIV/0! | F30: =IF(DAY(J$11)=0,"",IF(MONTH(J$11)<>MONTH($B30),"",YEAR($B30)-YEAR(J$11))) | H30: 0 | I30: =I29*(1+H30) -> 0 | L30: =D30+J30 -> 0 | M30: =I30+K30 -> 0 | P30: =((O30/O29)-1) -> #DIV/0! | Q30: =IF(DAY(U$11)=0,"",IF(MONTH(U$11)<>MONTH($B30),"",YEAR($B30)-YEAR(U$11))) | S30: 0 | T30: =T29*(1+S30) -> 0 | W30: =O30+U30 -> 0 | X30: =T30+V30 -> 0 | AA30: =((Z30/Z29)-1) -> #DIV/0! | AB30: =IF(DAY(AF$11)=0,"",IF(MONTH(AF$11)<>MONTH($B30),"",YEAR($B30)-YEAR(AF$11))) | AD30: 0 | AE30: =AE29*(1+AD30) -> 0 | AH30: =Z30+AF30 -> 0 | AI30: =AE30+AG30 -> 0 | AL30: 38504 | AM30: =L30+W30+AH30 -> 0 | AN30: =((AM30/AM29)-1) -> #DIV/0! | AO30: =M30+X30+AI30 -> 0 | AP30: =((AO30/AO29)-1) -> #DIV/0! | AR30: 34.076019 | AV30: =((AU30/AU29)-1) -> #DIV/0!
B31: 38534 | E31: =((D31/D30)-1) -> #DIV/0! | F31: =IF(DAY(J$11)=0,"",IF(MONTH(J$11)<>MONTH($B31),"",YEAR($B31)-YEAR(J$11))) | G31: Anual | H31: 0.1169 | I31: =I30*(1+H31) -> 0 | L31: =D31+J31 -> 0 | M31: =I31+K31 -> 0 | P31: =((O31/O30)-1) -> #DIV/0! | Q31: =IF(DAY(U$11)=0,"",IF(MONTH(U$11)<>MONTH($B31),"",YEAR($B31)-YEAR(U$11))) | R31: Anual | S31: 0.1169 | T31: =T30*(1+S31) -> 0 | W31: =O31+U31 -> 0 | X31: =T31+V31 -> 0 | AA31: =((Z31/Z30)-1) -> #DIV/0! | AB31: =IF(DAY(AF$11)=0,"",IF(MONTH(AF$11)<>MONTH($B31),"",YEAR($B31)-YEAR(AF$11))) | AC31: Anual | AD31: 0.1169 | AE31: =AE30*(1+AD31) -> 0 | AH31: =Z31+AF31 -> 0 | AI31: =AE31+AG31 -> 0 | AL31: 38534 | AM31: =L31+W31+AH31 -> 0 | AN31: =((AM31/AM30)-1) -> #DIV/0! | AO31: =M31+X31+AI31 -> 0 | AP31: =((AO31/AO30)-1) -> #DIV/0! | AR31: 34.038535 | AV31: =((AU31/AU30)-1) -> #DIV/0!
B32: 38565 | E32: =((D32/D31)-1) -> #DIV/0! | F32: =IF(DAY(J$11)=0,"",IF(MONTH(J$11)<>MONTH($B32),"",YEAR($B32)-YEAR(J$11))) | H32: 0 | I32: =I31*(1+H32) -> 0 | L32: =D32+J32 -> 0 | M32: =I32+K32 -> 0 | P32: =((O32/O31)-1) -> #DIV/0! | Q32: =IF(DAY(U$11)=0,"",IF(MONTH(U$11)<>MONTH($B32),"",YEAR($B32)-YEAR(U$11))) | S32: 0 | T32: =T31*(1+S32) -> 0 | W32: =O32+U32 -> 0 | X32: =T32+V32 -> 0 | AA32: =((Z32/Z31)-1) -> #DIV/0! | AB32: =IF(DAY(AF$11)=0,"",IF(MONTH(AF$11)<>MONTH($B32),"",YEAR($B32)-YEAR(AF$11))) | AD32: 0 | AE32: =AE31*(1+AD32) -> 0 | AH32: =Z32+AF32 -> 0 | AI32: =AE32+AG32 -> 0 | AL32: 38565 | AM32: =L32+W32+AH32 -> 0 | AN32: =((AM32/AM31)-1) -> #DIV/0! | AO32: =M32+X32+AI32 -> 0 | AP32: =((AO32/AO31)-1) -> #DIV/0! | AR32: 34.048746 | AV32: =((AU32/AU31)-1) -> #DIV/0!
B33: 38596 | E33: =((D33/D32)-1) -> #DIV/0! | F33: =IF(DAY(J$11)=0,"",IF(MONTH(J$11)<>MONTH($B33),"",YEAR($B33)-YEAR(J$11))) | H33: 0 | I33: =I32*(1+H33) -> 0 | L33: =D33+J33 -> 0 | M33: =I33+K33 -> 0 | P33: =((O33/O32)-1) -> #DIV/0! | Q33: =IF(DAY(U$11)=0,"",IF(MONTH(U$11)<>MONTH($B33),"",YEAR($B33)-YEAR(U$11))) | S33: 0 | T33: =T32*(1+S33) -> 0 | W33: =O33+U33 -> 0 | X33: =T33+V33 -> 0 | AA33: =((Z33/Z32)-1) -> #DIV/0! | AB33: =IF(DAY(AF$11)=0,"",IF(MONTH(AF$11)<>MONTH($B33),"",YEAR($B33)-YEAR(AF$11))) | AD33: 0 | AE33: =AE32*(1+AD33) -> 0 | AH33: =Z33+AF33 -> 0 | AI33: =AE33+AG33 -> 0 | AL33: 38596 | AM33: =L33+W33+AH33 -> 0 | AN33: =((AM33/AM32)-1) -> #DIV/0! | AO33: =M33+X33+AI33 -> 0 | AP33: =((AO33/AO32)-1) -> #DIV/0! | AR33: 34.048746 | AV33: =((AU33/AU32)-1) -> #DIV/0!
B34: 38626 | E34: =((D34/D33)-1) -> #DIV/0! | F34: =IF(DAY(J$11)=0,"",IF(MONTH(J$11)<>MONTH($B34),"",YEAR($B34)-YEAR(J$11))) | H34: 0 | I34: =I33*(1+H34) -> 0 | L34: =D34+J34 -> 0 | M34: =I34+K34 -> 0 | P34: =((O34/O33)-1) -> #DIV/0! | Q34: =IF(DAY(U$11)=0,"",IF(MONTH(U$11)<>MONTH($B34),"",YEAR($B34)-YEAR(U$11))) | S34: 0 | T34: =T33*(1+S34) -> 0 | W34: =O34+U34 -> 0 | X34: =T34+V34 -> 0 | AA34: =((Z34/Z33)-1) -> #DIV/0! | AB34: =IF(DAY(AF$11)=0,"",IF(MONTH(AF$11)<>MONTH($B34),"",YEAR($B34)-YEAR(AF$11))) | AD34: 0 | AE34: =AE33*(1+AD34) -> 0 | AH34: =Z34+AF34 -> 0 | AI34: =AE34+AG34 -> 0 | AL34: 38626 | AM34: =L34+W34+AH34 -> 0 | AN34: =((AM34/AM33)-1) -> #DIV/0! | AO34: =M34+X34+AI34 -> 0 | AP34: =((AO34/AO33)-1) -> #DIV/0! | AR34: 34.099819 | AV34: =((AU34/AU33)-1) -> #DIV/0!
B35: 38657 | E35: =((D35/D34)-1) -> #DIV/0! | F35: =IF(DAY(J$11)=0,"",IF(MONTH(J$11)<>MONTH($B35),"",YEAR($B35)-YEAR(J$11))) | H35: 0 | I35: =I34*(1+H35) -> 0 | L35: =D35+J35 -> 0 | M35: =I35+K35 -> 0 | P35: =((O35/O34)-1) -> #DIV/0! | Q35: =IF(DAY(U$11)=0,"",IF(MONTH(U$11)<>MONTH($B35),"",YEAR($B35)-YEAR(U$11))) | S35: 0 | T35: =T34*(1+S35) -> 0 | W35: =O35+U35 -> 0 | X35: =T35+V35 -> 0 | AA35: =((Z35/Z34)-1) -> #DIV/0! | AB35: =IF(DAY(AF$11)=0,"",IF(MONTH(AF$11)<>MONTH($B35),"",YEAR($B35)-YEAR(AF$11))) | AD35: 0 | AE35: =AE34*(1+AD35) -> 0 | AH35: =Z35+AF35 -> 0 | AI35: =AE35+AG35 -> 0 | AL35: 38657 | AM35: =L35+W35+AH35 -> 0 | AN35: =((AM35/AM34)-1) -> #DIV/0! | AO35: =M35+X35+AI35 -> 0 | AP35: =((AO35/AO34)-1) -> #DIV/0! | AR35: 34.297597 | AV35: =((AU35/AU34)-1) -> #DIV/0!
B36: 38687 | E36: =((D36/D35)-1) -> #DIV/0! | F36: =IF(DAY(J$11)=0,"",IF(MONTH(J$11)<>MONTH($B36),"",YEAR($B36)-YEAR(J$11))) | H36: 0 | I36: =I35*(1+H36) -> 0 | L36: =D36+J36 -> 0 | M36: =I36+K36 -> 0 | P36: =((O36/O35)-1) -> #DIV/0! | Q36: =IF(DAY(U$11)=0,"",IF(MONTH(U$11)<>MONTH($B36),"",YEAR($B36)-YEAR(U$11))) | S36: 0 | T36: =T35*(1+S36) -> 0 | W36: =O36+U36 -> 0 | X36: =T36+V36 -> 0 | AA36: =((Z36/Z35)-1) -> #DIV/0! | AB36: =IF(DAY(AF$11)=0,"",IF(MONTH(AF$11)<>MONTH($B36),"",YEAR($B36)-YEAR(AF$11))) | AD36: 0 | AE36: =AE35*(1+AD36) -> 0 | AH36: =Z36+AF36 -> 0 | AI36: =AE36+AG36 -> 0 | AL36: 38687 | AM36: =L36+W36+AH36 -> 0 | AN36: =((AM36/AM35)-1) -> #DIV/0! | AO36: =M36+X36+AI36 -> 0 | AP36: =((AO36/AO35)-1) -> #DIV/0! | AR36: 34.482804 | AV36: =((AU36/AU35)-1) -> #DIV/0!
A37: 2006 | B37: 38718 | E37: =((D37/D36)-1) -> #DIV/0! | F37: =IF(DAY(J$11)=0,"",IF(MONTH(J$11)<>MONTH($B37),"",YEAR($B37)-YEAR(J$11))) | H37: 0 | I37: =I36*(1+H37) -> 0 | L37: =D37+J37 -> 0 | M37: =I37+K37 -> 0 | P37: =((O37/O36)-1) -> #DIV/0! | Q37: =IF(DAY(U$11)=0,"",IF(MONTH(U$11)<>MONTH($B37),"",YEAR($B37)-YEAR(U$11))) | S37: 0 | T37: =T36*(1+S37) -> 0 | W37: =O37+U37 -> 0 | X37: =T37+V37 -> 0 | AA37: =((Z37/Z36)-1) -> #DIV/0! | AB37: =IF(DAY(AF$11)=0,"",IF(MONTH(AF$11)<>MONTH($B37),"",YEAR($B37)-YEAR(AF$11))) | AD37: 0 | AE37: =AE36*(1+AD37) -> 0 | AH37: =Z37+AF37 -> 0 | AI37: =AE37+AG37 -> 0 | AK37: 2006 | AL37: 38718 | AM37: =L37+W37+AH37 -> 0 | AN37: =((AM37/AM36)-1) -> #DIV/0! | AO37: =M37+X37+AI37 -> 0 | AP37: =((AO37/AO36)-1) -> #DIV/0! | AR37: 34.620735 | AV37: =((AU37/AU36)-1) -> #DIV/0!
B38: 38749 | E38: =((D38/D37)-1) -> #DIV/0! | F38: =IF(DAY(J$11)=0,"",IF(MONTH(J$11)<>MONTH($B38),"",YEAR($B38)-YEAR(J$11))) | H38: 0 | I38: =I37*(1+H38) -> 0 | L38: =D38+J38 -> 0 | M38: =I38+K38 -> 0 | P38: =((O38/O37)-1) -> #DIV/0! | Q38: =IF(DAY(U$11)=0,"",IF(MONTH(U$11)<>MONTH($B38),"",YEAR($B38)-YEAR(U$11))) | S38: 0 | T38: =T37*(1+S38) -> 0 | W38: =O38+U38 -> 0 | X38: =T38+V38 -> 0 | AA38: =((Z38/Z37)-1) -> #DIV/0! | AB38: =IF(DAY(AF$11)=0,"",IF(MONTH(AF$11)<>MONTH($B38),"",YEAR($B38)-YEAR(AF$11))) | AD38: 0 | AE38: =AE37*(1+AD38) -> 0 | AH38: =Z38+AF38 -> 0 | AI38: =AE38+AG38 -> 0 | AL38: 38749 | AM38: =L38+W38+AH38 -> 0 | AN38: =((AM38/AM37)-1) -> #DIV/0! | AO38: =M38+X38+AI38 -> 0 | AP38: =((AO38/AO37)-1) -> #DIV/0! | AR38: 34.752293 | AV38: =((AU38/AU37)-1) -> #DIV/0!
B39: 38777 | E39: =((D39/D38)-1) -> #DIV/0! | F39: =IF(DAY(J$11)=0,"",IF(MONTH(J$11)<>MONTH($B39),"",YEAR($B39)-YEAR(J$11))) | H39: 0 | I39: =I38*(1+H39) -> 0 | L39: =D39+J39 -> 0 | M39: =I39+K39 -> 0 | P39: =((O39/O38)-1) -> #DIV/0! | Q39: =IF(DAY(U$11)=0,"",IF(MONTH(U$11)<>MONTH($B39),"",YEAR($B39)-YEAR(U$11))) | S39: 0 | T39: =T38*(1+S39) -> 0 | W39: =O39+U39 -> 0 | X39: =T39+V39 -> 0 | AA39: =((Z39/Z38)-1) -> #DIV/0! | AB39: =IF(DAY(AF$11)=0,"",IF(MONTH(AF$11)<>MONTH($B39),"",YEAR($B39)-YEAR(AF$11))) | AD39: 0 | AE39: =AE38*(1+AD39) -> 0 | AH39: =Z39+AF39 -> 0 | AI39: =AE39+AG39 -> 0 | AL39: 38777 | AM39: =L39+W39+AH39 -> 0 | AN39: =((AM39/AM38)-1) -> #DIV/0! | AO39: =M39+X39+AI39 -> 0 | AP39: =((AO39/AO38)-1) -> #DIV/0! | AR39: 34.832223 | AV39: =((AU39/AU38)-1) -> #DIV/0!
B40: 38808 | E40: =((D40/D39)-1) -> #DIV/0! | F40: =IF(DAY(J$11)=0,"",IF(MONTH(J$11)<>MONTH($B40),"",YEAR($B40)-YEAR(J$11))) | H40: 0 | I40: =I39*(1+H40) -> 0 | L40: =D40+J40 -> 0 | M40: =I40+K40 -> 0 | P40: =((O40/O39)-1) -> #DIV/0! | Q40: =IF(DAY(U$11)=0,"",IF(MONTH(U$11)<>MONTH($B40),"",YEAR($B40)-YEAR(U$11))) | S40: 0 | T40: =T39*(1+S40) -> 0 | W40: =O40+U40 -> 0 | X40: =T40+V40 -> 0 | AA40: =((Z40/Z39)-1) -> #DIV/0! | AB40: =IF(DAY(AF$11)=0,"",IF(MONTH(AF$11)<>MONTH($B40),"",YEAR($B40)-YEAR(AF$11))) | AD40: 0 | AE40: =AE39*(1+AD40) -> 0 | AH40: =Z40+AF40 -> 0 | AI40: =AE40+AG40 -> 0 | AL40: 38808 | AM40: =L40+W40+AH40 -> 0 | AN40: =((AM40/AM39)-1) -> #DIV/0! | AO40: =M40+X40+AI40 -> 0 | AP40: =((AO40/AO39)-1) -> #DIV/0! | AR40: 34.92627 | AV40: =((AU40/AU39)-1) -> #DIV/0!
B41: 38838 | E41: =((D41/D40)-1) -> #DIV/0! | F41: =IF(DAY(J$11)=0,"",IF(MONTH(J$11)<>MONTH($B41),"",YEAR($B41)-YEAR(J$11))) | H41: 0 | I41: =I40*(1+H41) -> 0 | L41: =D41+J41 -> 0 | M41: =I41+K41 -> 0 | P41: =((O41/O40)-1) -> #DIV/0! | Q41: =IF(DAY(U$11)=0,"",IF(MONTH(U$11)<>MONTH($B41),"",YEAR($B41)-YEAR(U$11))) | S41: 0 | T41: =T40*(1+S41) -> 0 | W41: =O41+U41 -> 0 | X41: =T41+V41 -> 0 | AA41: =((Z41/Z40)-1) -> #DIV/0! | AB41: =IF(DAY(AF$11)=0,"",IF(MONTH(AF$11)<>MONTH($B41),"",YEAR($B41)-YEAR(AF$11))) | AD41: 0 | AE41: =AE40*(1+AD41) -> 0 | AH41: =Z41+AF41 -> 0 | AI41: =AE41+AG41 -> 0 | AL41: 38838 | AM41: =L41+W41+AH41 -> 0 | AN41: =((AM41/AM40)-1) -> #DIV/0! | AO41: =M41+X41+AI41 -> 0 | AP41: =((AO41/AO40)-1) -> #DIV/0! | AR41: 34.968181 | AV41: =((AU41/AU40)-1) -> #DIV/0!
B42: 38869 | E42: =((D42/D41)-1) -> #DIV/0! | F42: =IF(DAY(J$11)=0,"",IF(MONTH(J$11)<>MONTH($B42),"",YEAR($B42)-YEAR(J$11))) | H42: 0 | I42: =I41*(1+H42) -> 0 | L42: =D42+J42 -> 0 | M42: =I42+K42 -> 0 | P42: =((O42/O41)-1) -> #DIV/0! | Q42: =IF(DAY(U$11)=0,"",IF(MONTH(U$11)<>MONTH($B42),"",YEAR($B42)-YEAR(U$11))) | S42: 0 | T42: =T41*(1+S42) -> 0 | W42: =O42+U42 -> 0 | X42: =T42+V42 -> 0 | AA42: =((Z42/Z41)-1) -> #DIV/0! | AB42: =IF(DAY(AF$11)=0,"",IF(MONTH(AF$11)<>MONTH($B42),"",YEAR($B42)-YEAR(AF$11))) | AD42: 0 | AE42: =AE41*(1+AD42) -> 0 | AH42: =Z42+AF42 -> 0 | AI42: =AE42+AG42 -> 0 | AL42: 38869 | AM42: =L42+W42+AH42 -> 0 | AN42: =((AM42/AM41)-1) -> #DIV/0! | AO42: =M42+X42+AI42 -> 0 | AP42: =((AO42/AO41)-1) -> #DIV/0! | AR42: 35.013639 | AV42: =((AU42/AU41)-1) -> #DIV/0!
B43: 38899 | E43: =((D43/D42)-1) -> #DIV/0! | F43: =IF(DAY(J$11)=0,"",IF(MONTH(J$11)<>MONTH($B43),"",YEAR($B43)-YEAR(J$11))) | G43: Anual | H43: 0.0889 | I43: =I42*(1+H43) -> 0 | L43: =D43+J43 -> 0 | M43: =I43+K43 -> 0 | P43: =((O43/O42)-1) -> #DIV/0! | Q43: =IF(DAY(U$11)=0,"",IF(MONTH(U$11)<>MONTH($B43),"",YEAR($B43)-YEAR(U$11))) | R43: Anual | S43: 0.0889 | T43: =T42*(1+S43) -> 0 | W43: =O43+U43 -> 0 | X43: =T43+V43 -> 0 | AA43: =((Z43/Z42)-1) -> #DIV/0! | AB43: =IF(DAY(AF$11)=0,"",IF(MONTH(AF$11)<>MONTH($B43),"",YEAR($B43)-YEAR(AF$11))) | AC43: Anual | AD43: 0.0889 | AE43: =AE42*(1+AD43) -> 0 | AH43: =Z43+AF43 -> 0 | AI43: =AE43+AG43 -> 0 | AL43: 38899 | AM43: =L43+W43+AH43 -> 0 | AN43: =((AM43/AM42)-1) -> #DIV/0! | AO43: =M43+X43+AI43 -> 0 | AP43: =((AO43/AO42)-1) -> #DIV/0! | AR43: 34.989129 | AV43: =((AU43/AU42)-1) -> #DIV/0!
B44: 38930 | E44: =((D44/D43)-1) -> #DIV/0! | F44: =IF(DAY(J$11)=0,"",IF(MONTH(J$11)<>MONTH($B44),"",YEAR($B44)-YEAR(J$11))) | H44: 0 | I44: =I43*(1+H44) -> 0 | L44: =D44+J44 -> 0 | M44: =I44+K44 -> 0 | P44: =((O44/O43)-1) -> #DIV/0! | Q44: =IF(DAY(U$11)=0,"",IF(MONTH(U$11)<>MONTH($B44),"",YEAR($B44)-YEAR(U$11))) | S44: 0 | T44: =T43*(1+S44) -> 0 | W44: =O44+U44 -> 0 | X44: =T44+V44 -> 0 | AA44: =((Z44/Z43)-1) -> #DIV/0! | AB44: =IF(DAY(AF$11)=0,"",IF(MONTH(AF$11)<>MONTH($B44),"",YEAR($B44)-YEAR(AF$11))) | AD44: 0 | AE44: =AE43*(1+AD44) -> 0 | AH44: =Z44+AF44 -> 0 | AI44: =AE44+AG44 -> 0 | AL44: 38930 | AM44: =L44+W44+AH44 -> 0 | AN44: =((AM44/AM43)-1) -> #DIV/0! | AO44: =M44+X44+AI44 -> 0 | AP44: =((AO44/AO43)-1) -> #DIV/0! | AR44: 35.027617 | AV44: =((AU44/AU43)-1) -> #DIV/0!
...

Sheet Calculo4Vidas
A1: DEMONSTRATIVO DE CÁLCULO
M3: Corr. monet. | N3: 45454
M4: Índice TJSP | N4: 100.83083
D6: Plano de saúde | I6: Categoria | M6: Tipo
D7: Mês aniv. cont. | I7: Vigência
D9: OBJETO | E9: Reajuste por Sinistralidade
D11: Nome | I11: Data Nasc. | O11: Nome | T11: Data Nasc. | Z11: Nome | AE11: Data Nasc. | AK11: Nome | AP11: Data Nasc. | AX11: TOTAL | BF11: TOTAL
A12: Ano | B12: Mês | D12: Valor pago | E12: Reaj. aplic. | F12: Idade | G12: Tipo reaj. | H12: Reaj. devido | I12: Vl. devido | J12: Extra Pago | K12: Extra devido | L12: TOTAL PAGO | M12: TOTAL DEVIDO | N12: Diferença | O12: Valor pago | P12: Reaj. aplic. | Q12: Idade | R12: Tipo reaj. | S12: Reaj. devido | T12: Vl. devido | U12: Extra Pago | V12: Extra devido | W12: TOTAL PAGO | X12: TOTAL DEVIDO | Y12: Diferença | Z12: Valor pago | AA12: Reaj. aplic. | AB12: Idade | AC12: Tipo reaj. | AD12: Reaj. devido | AE12: Vl. devido | AF12: Extra Pago | AG12: Extra devido | AH12: TOTAL PAGO | AI12: TOTAL DEVIDO | AJ12: Diferença | AK12: Valor pago | AL12: Reaj. aplic. | AM12: Idade | AN12: Tipo reaj. | AO12: Reaj. devido | AP12: Vl. devido | AQ12: Extra Pago | AR12: Extra devido | AS12: TOTAL PAGO | AT12: TOTAL DEVIDO | AU12: Diferença | AV12: Ano | AW12: Mês | AX12: Vl. tot. pago | AY12: Reaj. aplic. | AZ12: Vl. tot. devido | BA12: Reaj. aplic. | BB12: Diferença | BC12: Índ corr monet | BD12: Diferença corrigida | BF12: Vl. tot. pago | BG12: Reaj. aplic.
A13: 2004 | B13: 37987 | E13: 0 | F13: =IF(DAY(J$11)=0,"",IF(MONTH(J$11)<>MONTH($B13),"",YEAR($B13)-YEAR(J$11))) | H13: 0 | I13: =D13 -> 0 | L13: =D13+J13 -> 0 | M13: =I13+K13 -> 0 | P13: 0 | Q13: =IF(DAY(U$11)=0,"",IF(MONTH(U$11)<>MONTH($B13),"",YEAR($B13)-YEAR(U$11))) | S13: 0 | T13: =O13 -> 0 | W13: =O13+U13 -> 0 | X13: =T13+V13 -> 0 | AA13: 0 | AB13: =IF(DAY(AF$11)=0,"",IF(MONTH(AF$11)<>MONTH($B13),"",YEAR($B13)-YEAR(AF$11))) | AD13: 0 | AE13: =Z13 -> 0 | AH13: =Z13+AF13 -> 0 | AI13: =AE13+AG13 -> 0 | AL13: 0 | AM13: =IF(DAY(AQ$11)=0,"",IF(MONTH(AQ$11)<>MONTH($B13),"",YEAR($B13)-YEAR(AQ$11))) | AO13: 0 | AP13: =AK13 -> 0 | AS13: =AK13+AQ13 -> 0 | AT13: =AP13+AR13 -> 0 | AV13: 2004 | AW13: 37987 | AX13: =L13+W13+AH13+AS13 -> 0 | AY13: 0 | AZ13: =M13+X13+AI13+AT13 -> 0 | BA13: 0 | BC13: 31.052744 | BG13: 0
B14: 38018 | E14: =((D14/D13)-1) -> #DIV/0! | F14: =IF(DAY(J$11)=0,"",IF(MONTH(J$11)<>MONTH($B14),"",YEAR($B14)-YEAR(J$11))) | H14: 0 | I14: =I13*(1+H14) -> 0 | L14: =D14+J14 -> 0 | M14: =I14+K14 -> 0 | P14: =((O14/O13)-1) -> #DIV/0! | Q14: =IF(DAY(U$11)=0,"",IF(MONTH(U$11)<>MONTH($B14),"",YEAR($B14)-YEAR(U$11))) | S14: 0 | T14: =T13*(1+S14) -> 0 | W14: =O14+U14 -> 0 | X14: =T14+V14 -> 0 | AA14: =((Z14/Z13)-1) -> #DIV/0! | AB14: =IF(DAY(AF$11)=0,"",IF(MONTH(AF$11)<>MONTH($B14),"",YEAR($B14)-YEAR(AF$11))) | AD14: 0 | AE14: =AE13*(1+AD14) -> 0 | AH14: =Z14+AF14 -> 0 | AI14: =AE14+AG14 -> 0 | AL14: =((AK14/AK13)-1) -> #DIV/0! | AM14: =IF(DAY(AQ$11)=0,"",IF(MONTH(AQ$11)<>MONTH($B14),"",YEAR($B14)-YEAR(AQ$11))) | AO14: 0 | AP14: =AP13*(1+AO14) -> 0 | AS14: =AK14+AQ14 -> 0 | AT14: =AP14+AR14 -> 0 | AW14: 38018 | AX14: =L14+W14+AH14+AS14 -> 0 | AY14: =((AX14/AX13)-1) -> #DIV/0! | AZ14: =M14+X14+AI14+AT14 -> 0 | BA14: =((AZ14/AZ13)-1) -> #DIV/0! | BC14: 31.310481 | BG14: =((BF14/BF13)-1) -> #DIV/0!
B15: 38047 | E15: =((D15/D14)-1) -> #DIV/0! | F15: =IF(DAY(J$11)=0,"",IF(MONTH(J$11)<>MONTH($B15),"",YEAR($B15)-YEAR(J$11))) | H15: 0 | I15: =I14*(1+H15) -> 0 | L15: =D15+J15 -> 0 | M15: =I15+K15 -> 0 | P15: =((O15/O14)-1) -> #DIV/0! | Q15: =IF(DAY(U$11)=0,"",IF(MONTH(U$11)<>MONTH($B15),"",YEAR($B15)-YEAR(U$11))) | S15: 0 | T15: =T14*(1+S15) -> 0 | W15: =O15+U15 -> 0 | X15: =T15+V15 -> 0 | AA15: =((Z15/Z14)-1) -> #DIV/0! | AB15: =IF(DAY(AF$11)=0,"",IF(MONTH(AF$11)<>MONTH($B15),"",YEAR($B15)-YEAR(AF$11))) | AD15: 0 | AE15: =AE14*(1+AD15) -> 0 | AH15: =Z15+AF15 -> 0 | AI15: =AE15+AG15 -> 0 | AL15: =((AK15/AK14)-1) -> #DIV/0! | AM15: =IF(DAY(AQ$11)=0,"",IF(MONTH(AQ$11)<>MONTH($B15),"",YEAR($B15)-YEAR(AQ$11))) | AO15: 0 | AP15: =AP14*(1+AO15) -> 0 | AS15: =AK15+AQ15 -> 0 | AT15: =AP15+AR15 -> 0 | AW15: 38047 | AX15: =L15+W15+AH15+AS15 -> 0 | AY15: =((AX15/AX14)-1) -> #DIV/0! | AZ15: =M15+X15+AI15+AT15 -> 0 | BA15: =((AZ15/AZ14)-1) -> #DIV/0! | BC15: 31.432591 | BG15: =((BF15/BF14)-1) -> #DIV/0!
B16: 38078 | E16: =((D16/D15)-1) -> #DIV/0! | F16: =IF(DAY(J$11)=0,"",IF(MONTH(J$11)<>MONTH($B16),"",YEAR($B16)-YEAR(J$11))) | H16: 0 | I16: =I15*(1+H16) -> 0 | L16: =D16+J16 -> 0 | M16: =I16+K16 -> 0 | P16: =((O16/O15)-1) -> #DIV/0! | Q16: =IF(DAY(U$11)=0,"",IF(MONTH(U$11)<>MONTH($B16),"",YEAR($B16)-YEAR(U$11))) | S16: 0 | T16: =T15*(1+S16) -> 0 | W16: =O16+U16 -> 0 | X16: =T16+V16 -> 0 | AA16: =((Z16/Z15)-1) -> #DIV/0! | AB16: =IF(DAY(AF$11)=0,"",IF(MONTH(AF$11)<>MONTH($B16),"",YEAR($B16)-YEAR(AF$11))) | AD16: 0 | AE16: =AE15*(1+AD16) -> 0 | AH16: =Z16+AF16 -> 0 | AI16: =AE16+AG16 -> 0 | AL16: =((AK16/AK15)-1) -> #DIV/0! | AM16: =IF(DAY(AQ$11)=0,"",IF(MONTH(AQ$11)<>MONTH($B16),"",YEAR($B16)-YEAR(AQ$11))) | AO16: 0 | AP16: =AP15*(1+AO16) -> 0 | AS16: =AK16+AQ16 -> 0 | AT16: =AP16+AR16 -> 0 | AW16: 38078 | AX16: =L16+W16+AH16+AS16 -> 0 | AY16: =((AX16/AX15)-1) -> #DIV/0! | AZ16: =M16+X16+AI16+AT16 -> 0 | BA16: =((AZ16/AZ15)-1) -> #DIV/0! | BC16: 31.611756 | BG16: =((BF16/BF15)-1) -> #DIV/0!
B17: 38108 | E17: =((D17/D16)-1) -> #DIV/0! | F17: =IF(DAY(J$11)=0,"",IF(MONTH(J$11)<>MONTH($B17),"",YEAR($B17)-YEAR(J$11))) | H17: 0 | I17: =I16*(1+H17) -> 0 | L17: =D17+J17 -> 0 | M17: =I17+K17 -> 0 | P17: =((O17/O16)-1) -> #DIV/0! | Q17: =IF(DAY(U$11)=0,"",IF(MONTH(U$11)<>MONTH($B17),"",YEAR($B17)-YEAR(U$11))) | S17: 0 | T17: =T16*(1+S17) -> 0 | W17: =O17+U17 -> 0 | X17: =T17+V17 -> 0 | AA17: =((Z17/Z16)-1) -> #DIV/0! | AB17: =IF(DAY(AF$11)=0,"",IF(MONTH(AF$11)<>MONTH($B17),"",YEAR($B17)-YEAR(AF$11))) | AD17: 0 | AE17: =AE16*(1+AD17) -> 0 | AH17: =Z17+AF17 -> 0 | AI17: =AE17+AG17 -> 0 | AL17: =((AK17/AK16)-1) -> #DIV/0! | AM17: =IF(DAY(AQ$11)=0,"",IF(MONTH(AQ$11)<>MONTH($B17),"",YEAR($B17)-YEAR(AQ$11))) | AO17: 0 | AP17: =AP16*(1+AO17) -> 0 | AS17: =AK17+AQ17 -> 0 | AT17: =AP17+AR17 -> 0 | AW17: 38108 | AX17: =L17+W17+AH17+AS17 -> 0 | AY17: =((AX17/AX16)-1) -> #DIV/0! | AZ17: =M17+X17+AI17+AT17 -> 0 | BA17: =((AZ17/AZ16)-1) -> #DIV/0! | BC17: 31.741364 | BG17: =((BF17/BF16)-1) -> #DIV/0!
